Workbook
Name Print_Area: 'Nota Mes'!$C$1:$AE$52

Sheet Evaluación
B3: Bien | C3: 90
B4: Regular | C4: 85
B5: Mal | C5: 70
B6: Muy Mal
B8: Cantidad | C8: 26

Sheet Nota Mes
C1: Año | D1: 2026
C2: Mes | D2: ene
C5: Valores | D5: Parque Diversiones Pueblo Antiguo | E5: Avenida Escazú | F5: Terramall | G5: Food Court Parque Diversiones | H5: Oxígeno | I5: Real Cariari | J5: Guadalupe | K5: Real Alajuela | L5: Cartago | M5: Alajuela | N5: Multiplaza Curridabat | O5: Coronado | P5: San José | Q5: Práctiko | R5: Tibás | S5: Lincoln | T5: Multiplaza Escazú | U5: Santa Ana | V5: Curridabat | W5: Desamparados | X5: City Mall | Y5: Heredia | Z5: Sabana | AA5: San Francisco | AB5: Escazú | AC5: Pinares | AD5: Total general
B6: % | C6: Total Puntos | D6: 97 | E6: 93 | F6: 91 | G6: 91 | H6: 90 | I6: 89 | J6: 88 | K6: 87 | L6: 86 | M6: 86 | N6: 86 | O6: 85 | P6: 85 | Q6: 85 | R6: 84 | S6: 84 | T6: 83 | U6: 83 | V6: 82 | W6: 78 | X6: 77 | Y6: 76 | Z6: 74 | AA6: 74 | AB6: 73 | AC6: 72 | AD6: 83.807692
C7: Cantidad evaluaciones | D7: 1 | E7: 1 | F7: 1 | G7: 1 | H7: 1 | I7: 1 | J7: 1 | K7: 1 | L7: 1 | M7: 1 | N7: 1 | O7: 1 | P7: 1 | Q7: 1 | R7: 1 | S7: 1 | T7: 1 | U7: 1 | V7: 1 | W7: 1 | X7: 1 | Y7: 1 | Z7: 1 | AA7: 1 | AB7: 1 | AC7: 1 | AD7: 26
B8: =((AD8/MAX(D8:AC8))/Evaluación!$C$8)*100 -> 96.153846 | C8: Limpieza exteriores | D8: 2 | E8: 2 | F8: 2 | G8: 2 | H8: 2 | I8: 2 | J8: 2 | K8: 2 | L8: 2 | M8: 2 | N8: 2 | O8: 2 | P8: 2 | Q8: 2 | R8: 2 | S8: 2 | T8: 2 | U8: 2 | V8: 2 | W8: 2 | X8: 2 | Y8: 2 | Z8: 2 | AA8: 2 | AB8: 2 | AC8: 0 | AD8: 50
B9: =((AD9/MAX(D9:AC9))/Evaluación!$C$8)*100 -> 65.384615 | C9: Áreas de Salón e Intermedio | D9: 2 | E9: 2 | F9: 2 | G9: 2 | H9: 0 | I9: 2 | J9: 2 | K9: 0 | L9: 2 | M9: 0 | N9: 2 | O9: 2 | P9: 2 | Q9: 0 | R9: 2 | S9: 0 | T9: 0 | U9: 0 | V9: 2 | W9: 2 | X9: 0 | Y9: 2 | Z9: 2 | AA9: 0 | AB9: 2 | AC9: 2 | AD9: 34
B10: =((AD10/MAX(D10:AC10))/Evaluación!$C$8)*100 -> 100 | C10: Baño Invitados | D10: 2 | E10: 2 | F10: 2 | G10: 2 | H10: 2 | I10: 2 | J10: 2 | K10: 2 | L10: 2 | M10: 2 | N10: 2 | O10: 2 | P10: 2 | Q10: 2 | R10: 2 | S10: 2 | T10: 2 | U10: 2 | V10: 2 | W10: 2 | X10: 2 | Y10: 2 | Z10: 2 | AA10: 2 | AB10: 2 | AC10: 2 | AD10: 52
B11: =((AD11/MAX(D11:AC11))/Evaluación!$C$8)*100 -> 96.153846 | C11: Documentación Legal | D11: 3 | E11: 3 | F11: 3 | G11: 3 | H11: 3 | I11: 3 | J11: 3 | K11: 3 | L11: 3 | M11: 3 | N11: 3 | O11: 3 | P11: 3 | Q11: 3 | R11: 3 | S11: 3 | T11: 3 | U11: 0 | V11: 3 | W11: 3 | X11: 3 | Y11: 3 | Z11: 3 | AA11: 3 | AB11: 3 | AC11: 3 | AD11: 75
B12: =((AD12/MAX(D12:AC12))/Evaluación!$C$8)*100 -> 100 | C12: Urna de Postres | D12: 2 | E12: 2 | F12: 2 | G12: 2 | H12: 2 | I12: 2 | J12: 2 | K12: 2 | L12: 2 | M12: 2 | N12: 2 | O12: 2 | P12: 2 | Q12: 2 | R12: 2 | S12: 2 | T12: 2 | U12: 2 | V12: 2 | W12: 2 | X12: 2 | Y12: 2 | Z12: 2 | AA12: 2 | AB12: 2 | AC12: 2 | AD12: 52
B13: =((AD13/MAX(D13:AC13))/Evaluación!$C$8)*100 -> 100 | C13: Área Serv. Exprés | D13: 2 | E13: 2 | F13: 2 | G13: 2 | H13: 2 | I13: 2 | J13: 2 | K13: 2 | L13: 2 | M13: 2 | N13: 2 | O13: 2 | P13: 2 | Q13: 2 | R13: 2 | S13: 2 | T13: 2 | U13: 2 | V13: 2 | W13: 2 | X13: 2 | Y13: 2 | Z13: 2 | AA13: 2 | AB13: 2 | AC13: 2 | AD13: 52
B14: =((AD14/MAX(D14:AC14))/Evaluación!$C$8)*100 -> 100 | C14: Personal de servicio Exprés | D14: 2 | E14: 2 | F14: 2 | G14: 2 | H14: 2 | I14: 2 | J14: 2 | K14: 2 | L14: 2 | M14: 2 | N14: 2 | O14: 2 | P14: 2 | Q14: 2 | R14: 2 | S14: 2 | T14: 2 | U14: 2 | V14: 2 | W14: 2 | X14: 2 | Y14: 2 | Z14: 2 | AA14: 2 | AB14: 2 | AC14: 2 | AD14: 52
B15: =((AD15/MAX(D15:AC15))/Evaluación!$C$8)*100 -> 100 | C15: PCC Maneno Term. | D15: 3 | E15: 3 | F15: 3 | G15: 3 | H15: 3 | I15: 3 | J15: 3 | K15: 3 | L15: 3 | M15: 3 | N15: 3 | O15: 3 | P15: 3 | Q15: 3 | R15: 3 | S15: 3 | T15: 3 | U15: 3 | V15: 3 | W15: 3 | X15: 3 | Y15: 3 | Z15: 3 | AA15: 3 | AB15: 3 | AC15: 3 | AD15: 78
B16: =((AD16/MAX(D16:AC16))/Evaluación!$C$8)*100 -> 88.461538 | C16: Puesto Lavado | D16: 3 | E16: 3 | F16: 3 | G16: 3 | H16: 3 | I16: 3 | J16: 3 | K16: 3 | L16: 3 | M16: 3 | N16: 3 | O16: 0 | P16: 3 | Q16: 3 | R16: 3 | S16: 0 | T16: 3 | U16: 3 | V16: 3 | W16: 3 | X16: 0 | Y16: 3 | Z16: 3 | AA16: 3 | AB16: 3 | AC16: 3 | AD16: 69 | AG16: s
B17: =((AD17/MAX(D17:AC17))/Evaluación!$C$8)*100 -> 76.923077 | C17: Puesto Lavado Manipuladores | D17: 2 | E17: 0 | F17: 2 | G17: 2 | H17: 2 | I17: 2 | J17: 2 | K17: 2 | L17: 2 | M17: 2 | N17: 2 | O17: 2 | P17: 0 | Q17: 2 | R17: 2 | S17: 2 | T17: 2 | U17: 2 | V17: 0 | W17: 2 | X17: 2 | Y17: 0 | Z17: 0 | AA17: 2 | AB17: 0 | AC17: 2 | AD17: 40
B18: =((AD18/MAX(D18:AC18))/Evaluación!$C$8)*100 -> 96.153846 | C18: Áreas de pilas rejilla | D18: 2 | E18: 2 | F18: 2 | G18: 2 | H18: 2 | I18: 2 | J18: 2 | K18: 2 | L18: 2 | M18: 2 | N18: 2 | O18: 2 | P18: 2 | Q18: 2 | R18: 2 | S18: 2 | T18: 2 | U18: 2 | V18: 2 | W18: 2 | X18: 2 | Y18: 2 | Z18: 2 | AA18: 0 | AB18: 2 | AC18: 2 | AD18: 50
B19: =((AD19/MAX(D19:AC19))/Evaluación!$C$8)*100 -> 61.538462 | C19: Área de pilas limpieza | D19: 2 | E19: 2 | F19: 2 | G19: 2 | H19: 2 | I19: 2 | J19: 2 | K19: 0 | L19: 2 | M19: 0 | N19: 2 | O19: 2 | P19: 2 | Q19: 0 | R19: 2 | S19: 2 | T19: 0 | U19: 0 | V19: 2 | W19: 0 | X19: 0 | Y19: 2 | Z19: 0 | AA19: 0 | AB19: 0 | AC19: 2 | AD19: 32
B20: =((AD20/MAX(D20:AC20))/Evaluación!$C$8)*100 -> 84.615385 | C20: Área de pilas delantal | D20: 2 | E20: 0 | F20: 2 | G20: 0 | H20: 2 | I20: 2 | J20: 0 | K20: 2 | L20: 2 | M20: 2 | N20: 2 | O20: 2 | P20: 2 | Q20: 2 | R20: 2 | S20: 2 | T20: 2 | U20: 2 | V20: 2 | W20: 2 | X20: 0 | Y20: 2 | Z20: 2 | AA20: 2 | AB20: 2 | AC20: 2 | AD20: 44
B21: =((AD21/MAX(D21:AC21))/Evaluación!$C$8)*100 -> 100 | C21: Área de pilas químicos | D21: 1 | E21: 1 | F21: 1 | G21: 1 | H21: 1 | I21: 1 | J21: 1 | K21: 1 | L21: 1 | M21: 1 | N21: 1 | O21: 1 | P21: 1 | Q21: 1 | R21: 1 | S21: 1 | T21: 1 | U21: 1 | V21: 1 | W21: 1 | X21: 1 | Y21: 1 | Z21: 1 | AA21: 1 | AB21: 1 | AC21: 1 | AD21: 26
B22: =((AD22/MAX(D22:AC22))/Evaluación!$C$8)*100 -> 100 | C22: Área de cocina Limpieza | D22: 1 | E22: 1 | F22: 1 | G22: 1 | H22: 1 | I22: 1 | J22: 1 | K22: 1 | L22: 1 | M22: 1 | N22: 1 | O22: 1 | P22: 1 | Q22: 1 | R22: 1 | S22: 1 | T22: 1 | U22: 1 | V22: 1 | W22: 1 | X22: 1 | Y22: 1 | Z22: 1 | AA22: 1 | AB22: 1 | AC22: 1 | AD22: 26
B23: =((AD23/MAX(D23:AC23))/Evaluación!$C$8)*100 -> 88.461538 | C23: Pañitos y utencilios | D23: 2 | E23: 2 | F23: 2 | G23: 0 | H23: 2 | I23: 2 | J23: 2 | K23: 2 | L23: 0 | M23: 2 | N23: 2 | O23: 2 | P23: 2 | Q23: 2 | R23: 2 | S23: 2 | T23: 2 | U23: 2 | V23: 2 | W23: 2 | X23: 2 | Y23: 2 | Z23: 2 | AA23: 0 | AB23: 2 | AC23: 2 | AD23: 46
B24: =((AD24/MAX(D24:AC24))/Evaluación!$C$8)*100 -> 61.538462 | C24: Equipos eléctricos | D24: 3 | E24: 3 | F24: 3 | G24: 3 | H24: 3 | I24: 3 | J24: 0 | K24: 0 | L24: 0 | M24: 3 | N24: 3 | O24: 3 | P24: 3 | Q24: 3 | R24: 0 | S24: 3 | T24: 3 | U24: 3 | V24: 0 | W24: 3 | X24: 3 | Y24: 0 | Z24: 0 | AA24: 0 | AB24: 0 | AC24: 0 | AD24: 48
B25: =((AD25/MAX(D25:AC25))/Evaluación!$C$8)*100 -> 42.307692 | C25: Equipos de almacenamiento | D25: 0 | E25: 3 | F25: 0 | G25: 3 | H25: 0 | I25: 3 | J25: 0 | K25: 0 | L25: 3 | M25: 0 | N25: 0 | O25: 0 | P25: 3 | Q25: 0 | R25: 3 | S25: 0 | T25: 0 | U25: 0 | V25: 3 | W25: 0 | X25: 0 | Y25: 3 | Z25: 3 | AA25: 3 | AB25: 0 | AC25: 3 | AD25: 33
B26: =((AD26/MAX(D26:AC26))/Evaluación!$C$8)*100 -> 23.076923 | C26: Equipos de Gas | D26: 3 | E26: 0 | F26: 3 | G26: 0 | H26: 0 | I26: 0 | J26: 3 | K26: 0 | L26: 0 | M26: 0 | N26: 0 | O26: 0 | P26: 0 | Q26: 3 | R26: 0 | S26: 3 | T26: 3 | U26: 0 | V26: 0 | W26: 0 | X26: 0 | Y26: 0 | Z26: 0 | AA26: 0 | AB26: 0 | AC26: 0 | AD26: 18
B27: =((AD27/MAX(D27:AC27))/Evaluación!$C$8)*100 -> 69.230769 | C27: Holding Gabinet Limpieza | D27: 2 | E27: 2 | F27: 2 | G27: 2 | H27: 2 | I27: 2 | J27: 2 | K27: 2 | L27: 0 | M27: 2 | N27: 0 | O27: 2 | P27: 2 | Q27: 2 | R27: 0 | S27: 2 | T27: 2 | U27: 2 | V27: 0 | W27: 0 | X27: 2 | Y27: 2 | Z27: 0 | AA27: 2 | AB27: 0 | AC27: 0 | AD27: 36
B28: =((AD28/MAX(D28:AC28))/Evaluación!$C$8)*100 -> 73.076923 | C28: Almacenamiento Alimentos | D28: 2 | E28: 2 | F28: 2 | G28: 0 | H28: 2 | I28: 2 | J28: 2 | K28: 2 | L28: 0 | M28: 0 | N28: 2 | O28: 2 | P28: 2 | Q28: 2 | R28: 0 | S28: 2 | T28: 0 | U28: 2 | V28: 2 | W28: 0 | X28: 0 | Y28: 2 | Z28: 2 | AA28: 2 | AB28: 2 | AC28: 2 | AD28: 38
... B52: =((AD52/MAX(D52:AC52))/Evaluación!$C$8)*100 -> 73.076923 | C52: Registro de cocción de pollo | D52: 4 | E52: 4 | F52: 4 | G52: 4 | H52: 4 | I52: 4 | J52: 4 | K52: 4 | L52: 4 | M52: 4 | N52: 4 | O52: 0 | P52: 4 | Q52: 0 | R52: 4 | S52: 0 | T52: 0 | U52: 4 | V52: 0 | W52: 4 | X52: 4 | Y52: 4 | Z52: 4 | AA52: 0 | AB52: 4 | AC52: 0 | AD52: 76

Sheet Datos
A1: ID | B1: Hora de inicio | C1: Hora de finalización | D1: Correo electrónico | E1: Nombre | F1: Total de puntos | G1: Comentarios del cuestionario | H1: Restaurante | I1: Puntos: Restaurante | J1: Comentarios: Restaurante | K1: Fecha de la evaluación | L1: Puntos: Fecha de la evaluación | M1: Comentarios: Fecha de la evaluación | N1: Nombre del administrativo a cargo del turno: | O1: Puntos: Nombre del administrativo a cargo del turno: | P1: Comentarios: Nombre del administrativo a cargo del turno: | Q1: Nombre del evaluador: | R1: Puntos: Nombre del evaluador: | S1: Comentarios: Nombre del evaluador: | T1: LIMPIEZA DE EXTERIORES: Exteriores del establecimiento limpios, ordenados. Jardín recortado, plantas en buen estado. | U1: Puntos: LIMPIEZA DE EXTERIORES: Exteriores del establecimiento limpios, ordenados. Jardín recortado, plantas en buen estado. | V1: Comentarios: LIMPIEZA DE EXTERIORES: Exteriores del establecimiento limpios, ordenados. Jardín recortado, plantas en buen estado. | W1: Comentarios pregunta 5: | X1: Puntos: Comentarios pregunta 5: | Y1: Comentarios: Comentarios pregunta 5: | Z1: AREAS DE SALON EN INTERMEDIO: Las áreas de salón e intermedio se encuentra en optimas condiciones de orden y limpieza. | AA1: Puntos: AREAS DE SALON EN INTERMEDIO: Las áreas de salón e intermedio se encuentra en optimas condiciones de orden y limpieza. | AB1: Comentarios: AREAS DE SALON EN INTERMEDIO: Las áreas de salón e intermedio se encuentra en optimas condiciones de orden y limpieza. | AC1: Comentarios pregunta #7: | AD1: Puntos: Comentarios pregunta #7: | AE1: Comentarios: Comentarios pregunta #7: | AF1: BAÑO DE CLIENTES: Baño de clientes en buenas condiciones: Limpio, ordenado y con buen olor. *Equipado con: puesto de lavado de manos (agua, jabón líquido, secador de aire caliente), papel higiénic... | AG1: Puntos: BAÑO DE CLIENTES: Baño de clientes en buenas condiciones: Limpio, ordenado y con buen olor. *Equipado con: puesto de lavado de manos (agua, jabón líquido, secador de aire caliente), papel higiénic... | AH1: Comentarios: BAÑO DE CLIENTES: Baño de clientes en buenas condiciones: Limpio, ordenado y con buen olor. *Equipado con: puesto de lavado de manos (agua, jabón líquido, secador de aire caliente), papel higiénic... | AI1: Comentarios pregunta #9: | AJ1: Puntos: Comentarios pregunta #9: | AK1: Comentarios: Comentarios pregunta #9: | AL1: DOCUMENTACION LEGAL: Permiso sanitario de funcionamiento (PSF), Patente Comercial y de Licores vigentes y colocadas en un lugar visible. Mínimo el 95% de los colaboradores cumplen con el carnet de... | AM1: Puntos: DOCUMENTACION LEGAL: Permiso sanitario de funcionamiento (PSF), Patente Comercial y de Licores vigentes y colocadas en un lugar visible. Mínimo el 95% de los colaboradores cumplen con el carnet de... | AN1: Comentarios: DOCUMENTACION LEGAL: Permiso sanitario de funcionamiento (PSF), Patente Comercial y de Licores vigentes y colocadas en un lugar visible. Mínimo el 95% de los colaboradores cumplen con el carnet de... | AO1: Comentarios pregunta #11: | AP1: Puntos: Comentarios pregunta #11: | AQ1: Comentarios: Comentarios pregunta #11: | AR1: URNA DE POSTRES: La urna de postres se encuentra bien presentada, sin faltande de postres, los mismos cumplen la con la presentación establecida según el perfil de producto, sin deterioro, deshidr... | AS1: Puntos: URNA DE POSTRES: La urna de postres se encuentra bien presentada, sin faltande de postres, los mismos cumplen la con la presentación establecida según el perfil de producto, sin deterioro, deshidr... | AT1: Comentarios: URNA DE POSTRES: La urna de postres se encuentra bien presentada, sin faltande de postres, los mismos cumplen la con la presentación establecida según el perfil de producto, sin deterioro, deshidr... | AU1: Comentarios pregunta #13: | AV1: Puntos: Comentarios pregunta #13: | AW1: Comentarios: Comentarios pregunta #13: | AX1: AREA DE SERVICIO EXPRESS: El área de servicio express se encuentra limpia, ordenada, bolsos de transportar alimentos limpios y en buenas condiciones. No se colocan en el piso. | AY1: Puntos: AREA DE SERVICIO EXPRESS: El área de servicio express se encuentra limpia, ordenada, bolsos de transportar alimentos limpios y en buenas condiciones. No se colocan en el piso. | AZ1: Comentarios: AREA DE SERVICIO EXPRESS: El área de servicio express se encuentra limpia, ordenada, bolsos de transportar alimentos limpios y en buenas condiciones. No se colocan en el piso. | BA1: Comentarios pregunta #15: | BB1: Puntos: Comentarios pregunta #15: | BC1: Comentarios: Comentarios pregunta #15: | BD1: PERSONAL DE SERVICIO EXPRESS: El personal de mensajería cuenta con uniforme limpio y buena presentación personal, BPM, normas internas de Rosti (maquillaje, joyas, barba, uso de redecilla, uñas c... | BE1: Puntos: PERSONAL DE SERVICIO EXPRESS: El personal de mensajería cuenta con uniforme limpio y buena presentación personal, BPM, normas internas de Rosti (maquillaje, joyas, barba, uso de redecilla, uñas c... | BF1: Comentarios: PERSONAL DE SERVICIO EXPRESS: El personal de mensajería cuenta con uniforme limpio y buena presentación personal, BPM, normas internas de Rosti (maquillaje, joyas, barba, uso de redecilla, uñas c... | BG1: Comentarios pregunta #17: | BH1: Puntos: Comentarios pregunta #17: | BI1: Comentarios: Comentarios pregunta #17: | BJ1: PCC MANEJO DE TERMÓMETRO: Termómetros se mantienen disponibles, limpios, en buen estado y con escala de acuerdo a su uso; cuenten con opción de lectura de grados Centígrados y grados Fahrenheit ... | BK1: Puntos: PCC MANEJO DE TERMÓMETRO: Termómetros se mantienen disponibles, limpios, en buen estado y con escala de acuerdo a su uso; cuenten con opción de lectura de grados Centígrados y grados Fahrenheit ... | BL1: Comentarios: PCC MANEJO DE TERMÓMETRO: Termómetros se mantienen disponibles, limpios, en buen estado y con escala de acuerdo a su uso; cuenten con opción de lectura de grados Centígrados y grados Fahrenheit ... | BM1: Comentarios pregunta #19: | BN1: Puntos: Comentarios pregunta #19: | BO1: Comentarios: Comentarios pregunta #19: | BP1: PUESTO DE LAVADO: El puesto de lavado de manos se encuentra debidamente equipado (agua, jabón desinfectante, basurero y papel toalla) y con las adecuadas condiciones de limpieza. Es de uso exclusi... | BQ1: Puntos: PUESTO DE LAVADO: El puesto de lavado de manos se encuentra debidamente equipado (agua, jabón desinfectante, basurero y papel toalla) y con las adecuadas condiciones de limpieza. Es de uso exclusi... | BR1: Comentarios: PUESTO DE LAVADO: El puesto de lavado de manos se encuentra debidamente equipado (agua, jabón desinfectante, basurero y papel toalla) y con las adecuadas condiciones de limpieza. Es de uso exclusi... | BS1: Comentarios pregunta #21: | BT1: Puntos: Comentarios pregunta #21: | BU1: Comentarios: Comentarios pregunta #21: | BV1: PUESTO DE LAVADO: Los manipuladores de alimentos se lavan sus manos cada vez que se puedan haber contaminado o en cuanto suene el timer, siguiendo el procedimiento correcto. Alarma sonora (timer) ... | BW1: Puntos: PUESTO DE LAVADO: Los manipuladores de alimentos se lavan sus manos cada vez que se puedan haber contaminado o en cuanto suene el timer, siguiendo el procedimiento correcto. Alarma sonora (timer) ... | BX1: Comentarios: PUESTO DE LAVADO: Los manipuladores de alimentos se lavan sus manos cada vez que se puedan haber contaminado o en cuanto suene el timer, siguiendo el procedimiento correcto. Alarma sonora (timer) ... | BY1: Comentarios pregunta #23: | BZ1: Puntos: Comentarios pregunta #23: | CA1: Comentarios: Comentarios pregunta #23: | CB1: AREA DE PILAS: Pilas cuentan con rejillas y sistema de retención de agua para lavado por inmersión. Tren de lavado funcionando de la manera correcta (lavado-enjuague- sanitización). Cumplen con mé... | CC1: Puntos: AREA DE PILAS: Pilas cuentan con rejillas y sistema de retención de agua para lavado por inmersión. Tren de lavado funcionando de la manera correcta (lavado-enjuague- sanitización). Cumplen con mé... | CD1: Comentarios: AREA DE PILAS: Pilas cuentan con rejillas y sistema de retención de agua para lavado por inmersión. Tren de lavado funcionando de la manera correcta (lavado-enjuague- sanitización). Cumplen con mé... | CE1: Comentarios pregunta # 25: | CF1: Puntos: Comentarios pregunta # 25: | CG1: Comentarios: Comentarios pregunta # 25: | CH1: AREA DE PILAS: limpia y ordenada, además no se identifica vajilla de la noche anterior sucia o con residuos en el área. Si el tiempo no permite realizar el proceso de lavado de la vajilla la noch... | CI1: Puntos: AREA DE PILAS: limpia y ordenada, además no se identifica vajilla de la noche anterior sucia o con residuos en el área. Si el tiempo no permite realizar el proceso de lavado de la vajilla la noch... | CJ1: Comentarios: AREA DE PILAS: limpia y ordenada, además no se identifica vajilla de la noche anterior sucia o con residuos en el área. Si el tiempo no permite realizar el proceso de lavado de la vajilla la noch... | CK1: Comentarios pregunta #27: | CL1: Puntos: Comentarios pregunta #27: | CM1: Comentarios: Comentarios pregunta #27: | CN1: AREA DE PILAS: Delantal blanco limpio y en buen estado. Canastas de escurrir vajilla limpias y en buen estado. Sin daños o presencia de hongos. El colaborador retira los residuos sólidos de la va... | CO1: Puntos: AREA DE PILAS: Delantal blanco limpio y en buen estado. Canastas de escurrir vajilla limpias y en buen estado. Sin daños o presencia de hongos. El colaborador retira los residuos sólidos de la va... | CP1: Comentarios: AREA DE PILAS: Delantal blanco limpio y en buen estado. Canastas de escurrir vajilla limpias y en buen estado. Sin daños o presencia de hongos. El colaborador retira los residuos sólidos de la va... | CQ1: Comentarios pregunta #29: | CR1: Puntos: Comentarios pregunta #29: | CS1: Comentarios: Comentarios pregunta #29: | CT1: AREA DE PILAS: Químicos en uso en pilas sin exceso de suciedad o material orgánico (grasa o alimentos). Sanitizante concentración mínima 200 ppm. | CU1: Puntos: AREA DE PILAS: Químicos en uso en pilas sin exceso de suciedad o material orgánico (grasa o alimentos). Sanitizante concentración mínima 200 ppm. | CV1: Comentarios: AREA DE PILAS: Químicos en uso en pilas sin exceso de suciedad o material orgánico (grasa o alimentos). Sanitizante concentración mínima 200 ppm. | CW1: Comentarios pregunta #31 | CX1: Puntos: Comentarios pregunta #31 | CY1: Comentarios: Comentarios pregunta #31 | CZ1: AREA DE COCINA: limpia y ordenada. No hay exceso de grasa o humedad en el piso. Muebles y repisas para almacenamiento con condiciones de limpieza adecuadas. | DA1: Puntos: AREA DE COCINA: limpia y ordenada. No hay exceso de grasa o humedad en el piso. Muebles y repisas para almacenamiento con condiciones de limpieza adecuadas. | DB1: Comentarios: AREA DE COCINA: limpia y ordenada. No hay exceso de grasa o humedad en el piso. Muebles y repisas para almacenamiento con condiciones de limpieza adecuadas. | DC1: Comentarios pregunta #33: | DD1: Puntos: Comentarios pregunta #33: | DE1: Comentarios: Comentarios pregunta #33: | DF1: PAÑITOS Y UTENSILIOS EN SOLUCIÓN SANITIZANTE: Los utensilios y pañitos que estan en uso, se mantienen en solución desinfectante de amonio cuaternario (mínimo 200 ppm.) El contenido de los recipi... | DG1: Puntos: PAÑITOS Y UTENSILIOS EN SOLUCIÓN SANITIZANTE: Los utensilios y pañitos que estan en uso, se mantienen en solución desinfectante de amonio cuaternario (mínimo 200 ppm.) El contenido de los recipi... | DH1: Comentarios: PAÑITOS Y UTENSILIOS EN SOLUCIÓN SANITIZANTE: Los utensilios y pañitos que estan en uso, se mantienen en solución desinfectante de amonio cuaternario (mínimo 200 ppm.) El contenido de los recipi... | DI1: Comentarios pregunta #35: | DJ1: Puntos: Comentarios pregunta #35: | DK1: Comentarios: Comentarios pregunta #35: | DL1: EQUIPOS ELECTRICOS: Limpios, en buen estado y funcionando correctamente (incluir abanicos) | DM1: Puntos: EQUIPOS ELECTRICOS: Limpios, en buen estado y funcionando correctamente (incluir abanicos) | DN1: Comentarios: EQUIPOS ELECTRICOS: Limpios, en buen estado y funcionando correctamente (incluir abanicos) | DO1: Comentarios pregunta #37: | DP1: Puntos: Comentarios pregunta #37: | DQ1: Comentarios: Comentarios pregunta #37: | DR1: EQUIPOS ALMACENAMIENTO FRIO: Limpios, en buen estado y funcionando correctamente. Las rejillas no se encuentran oxidadas. Cuentan con los empaques en buen estado. (Cámaras de refrigeración y cong... | DS1: Puntos: EQUIPOS ALMACENAMIENTO FRIO: Limpios, en buen estado y funcionando correctamente. Las rejillas no se encuentran oxidadas. Cuentan con los empaques en buen estado. (Cámaras de refrigeración y cong... | DT1: Comentarios: EQUIPOS ALMACENAMIENTO FRIO: Limpios, en buen estado y funcionando correctamente. Las rejillas no se encuentran oxidadas. Cuentan con los empaques en buen estado. (Cámaras de refrigeración y cong... | DU1: Comentarios pregunta #39: | DV1: Puntos: Comentarios pregunta #39: | DW1: Comentarios: Comentarios pregunta #39: | DX1: EQUIPOS DE GAS: Limpios, en buen estado y funcionando correctamente. El color de la llama es azul y no genera hollín. (freidores, plancha, olla arrocerra, horno, hornillón). Canastas de los freido... | DY1: Puntos: EQUIPOS DE GAS: Limpios, en buen estado y funcionando correctamente. El color de la llama es azul y no genera hollín. (freidores, plancha, olla arrocerra, horno, hornillón). Canastas de los freido... | DZ1: Comentarios: EQUIPOS DE GAS: Limpios, en buen estado y funcionando correctamente. El color de la llama es azul y no genera hollín. (freidores, plancha, olla arrocerra, horno, hornillón). Canastas de los freido... | EA1: Comentarios pregunta #41: | EB1: Puntos: Comentarios pregunta #41: | EC1: Comentarios: Comentarios pregunta #41: | ED1: HOLDING CABINET: Equipo limpio y en buen estado. Empaques en buen estado. Bandeja con agua para mantener la humedad del producto. | EE1: Puntos: HOLDING CABINET: Equipo limpio y en buen estado. Empaques en buen estado. Bandeja con agua para mantener la humedad del producto. | EF1: Comentarios: HOLDING CABINET: Equipo limpio y en buen estado. Empaques en buen estado. Bandeja con agua para mantener la humedad del producto. | EG1: Comentarios pregunta #43: | EH1: Puntos: Comentarios pregunta #43: | EI1: Comentarios: Comentarios pregunta #43: | EJ1: ALMACENAMIENTO DE LOS ALIMENTOS: Los alimentos deben mantenerse correctamente fechados y cubiertos (tapa o plástico adhesivo). Protegidos de contaminantes. Albahaca se mantiene en agua fresca, no ... | EK1: Puntos: ALMACENAMIENTO DE LOS ALIMENTOS: Los alimentos deben mantenerse correctamente fechados y cubiertos (tapa o plástico adhesivo). Protegidos de contaminantes. Albahaca se mantiene en agua fresca, no ... | EL1: Comentarios: ALMACENAMIENTO DE LOS ALIMENTOS: Los alimentos deben mantenerse correctamente fechados y cubiertos (tapa o plástico adhesivo). Protegidos de contaminantes. Albahaca se mantiene en agua fresca, no ... | EM1: Comentarios pregunta #45: | EN1: Puntos: Comentarios pregunta #45: | EO1: Comentarios: Comentarios pregunta #45: | EP1: VIDA UTIL Y ROTACION DE LOS ALIMENTOS: Se respeta la vida útil de todas las materias primas y productos preparados así como la rotación de los mismos cumpliendo con el método PEPS | EQ1: Puntos: VIDA UTIL Y ROTACION DE LOS ALIMENTOS: Se respeta la vida útil de todas las materias primas y productos preparados así como la rotación de los mismos cumpliendo con el método PEPS | ER1: Comentarios: VIDA UTIL Y ROTACION DE LOS ALIMENTOS: Se respeta la vida útil de todas las materias primas y productos preparados así como la rotación de los mismos cumpliendo con el método PEPS | ES1: Comentarios pregunta #47: | ET1: Puntos: Comentarios pregunta #47: | EU1: Comentarios: Comentarios pregunta #47: | EV1: ACEITE DE FREIDOR: temperatura 335C-350 C, sin humear y calidad correcta. Llenado correcto, no debe estar menos del límite mínimo ni más del límite máximo. | EW1: Puntos: ACEITE DE FREIDOR: temperatura 335C-350 C, sin humear y calidad correcta. Llenado correcto, no debe estar menos del límite mínimo ni más del límite máximo. | EX1: Comentarios: ACEITE DE FREIDOR: temperatura 335C-350 C, sin humear y calidad correcta. Llenado correcto, no debe estar menos del límite mínimo ni más del límite máximo. | EY1: Comentarios pregunta #49: | EZ1: Puntos: Comentarios pregunta #49: | FA1: Comentarios: Comentarios pregunta #49: | FB1: MANEJO DE POLLO CRUDO EN ZONA DEL FREIDOR: Se hace uso de la pinza amarilla o guantes para su manipulaciòn. El producto (pollo), se encuentra tapado para evitar deshidratación y contaminación. | FC1: Puntos: MANEJO DE POLLO CRUDO EN ZONA DEL FREIDOR: Se hace uso de la pinza amarilla o guantes para su manipulaciòn. El producto (pollo), se encuentra tapado para evitar deshidratación y contaminación. | FD1: Comentarios: MANEJO DE POLLO CRUDO EN ZONA DEL FREIDOR: Se hace uso de la pinza amarilla o guantes para su manipulaciòn. El producto (pollo), se encuentra tapado para evitar deshidratación y contaminación. | FE1: Comentarios pregunta #51: | FF1: Puntos: Comentarios pregunta #51: | FG1: Comentarios: Comentarios pregunta #51: | FH1: MANEJO CORRECTO DE LOS ALIMENTOS Y DESCONGELACIÓN: Los alimentos no se mantienen dentro de la zona de peligro (5°C a 60°C). Los alimentos congelados se descongelan siguiendo los procedimientos apr... | FI1: Puntos: MANEJO CORRECTO DE LOS ALIMENTOS Y DESCONGELACIÓN: Los alimentos no se mantienen dentro de la zona de peligro (5°C a 60°C). Los alimentos congelados se descongelan siguiendo los procedimientos apr... | FJ1: Comentarios: MANEJO CORRECTO DE LOS ALIMENTOS Y DESCONGELACIÓN: Los alimentos no se mantienen dentro de la zona de peligro (5°C a 60°C). Los alimentos congelados se descongelan siguiendo los procedimientos apr... | FK1: Comentarios pregunta #53: | FL1: Puntos: Comentarios pregunta #53: | FM1: Comentarios: Comentarios pregunta #53: | FN1: PROCESO DE ENFRIAMIENTO: Los alimentos sobrantes se enfrían siguiendo los procedimientos establecidos. | FO1: Puntos: PROCESO DE ENFRIAMIENTO: Los alimentos sobrantes se enfrían siguiendo los procedimientos establecidos. | FP1: Comentarios: PROCESO DE ENFRIAMIENTO: Los alimentos sobrantes se enfrían siguiendo los procedimientos establecidos. | FQ1: Comentarios pregunta #55: | FR1: Puntos: Comentarios pregunta #55: | FS1: Comentarios: Comentarios pregunta #55: | FT1: RECALENTAMIENTO Y MANTENIMIENTO DE LOS ALIMENTOS: el alimento debe alcanzar una temperatura mínima de 74°C al centro o en su parte más gruesa por 15 segundos posteriormente mantenerse a una tem... | FU1: Puntos: RECALENTAMIENTO Y MANTENIMIENTO DE LOS ALIMENTOS: el alimento debe alcanzar una temperatura mínima de 74°C al centro o en su parte más gruesa por 15 segundos posteriormente mantenerse a una tem... | FV1: Comentarios: RECALENTAMIENTO Y MANTENIMIENTO DE LOS ALIMENTOS: el alimento debe alcanzar una temperatura mínima de 74°C al centro o en su parte más gruesa por 15 segundos posteriormente mantenerse a una tem... | FW1: Comentarios pregunta #57: | FX1: Puntos: Comentarios pregunta #57: | FY1: Comentarios: Comentarios pregunta #57: | FZ1: BASUREROS: Basureros internos se deben mantener limpios, sin mal olor, bolsa ajustada, los basureros de mayor uso deben de contar al menos con tapa reducida. | GA1: Puntos: BASUREROS: Basureros internos se deben mantener limpios, sin mal olor, bolsa ajustada, los basureros de mayor uso deben de contar al menos con tapa reducida. | GB1: Comentarios: BASUREROS: Basureros internos se deben mantener limpios, sin mal olor, bolsa ajustada, los basureros de mayor uso deben de contar al menos con tapa reducida. | GC1: Comentarios pregunta #59: | GD1: Puntos: Comentarios pregunta #59: | GE1: Comentarios: Comentarios pregunta #59: | GF1: PROCEDIMIENTO DE REVISIÓN DE LECHUGA: Se cumple con la revisión de la lechuga hoja por hoja antes del proceso de corte con el fin de identificar algún posible cuerpo extraño (insecto). En caso de ... | GG1: Puntos: PROCEDIMIENTO DE REVISIÓN DE LECHUGA: Se cumple con la revisión de la lechuga hoja por hoja antes del proceso de corte con el fin de identificar algún posible cuerpo extraño (insecto). En caso de ... | GH1: Comentarios: PROCEDIMIENTO DE REVISIÓN DE LECHUGA: Se cumple con la revisión de la lechuga hoja por hoja antes del proceso de corte con el fin de identificar algún posible cuerpo extraño (insecto). En caso de ... | GI1: Comentarios pregunta #61: | GJ1: Puntos: Comentarios pregunta #61: | GK1: Comentarios: Comentarios pregunta #61: | GL1: AREA DE POLLO CRUDO: limpia, ordenada y sin presencia de mal olor. Pila de pollo cuenta con rejilla o Rhino para la retención de desechos sólidos. | GM1: Puntos: AREA DE POLLO CRUDO: limpia, ordenada y sin presencia de mal olor. Pila de pollo cuenta con rejilla o Rhino para la retención de desechos sólidos. | GN1: Comentarios: AREA DE POLLO CRUDO: limpia, ordenada y sin presencia de mal olor. Pila de pollo cuenta con rejilla o Rhino para la retención de desechos sólidos. | GO1: Comentarios pregunta #63: | GP1: Puntos: Comentarios pregunta #63: | GQ1: Comentarios: Comentarios pregunta #63: | GR1: MANEJO DE POLLO CRUDO Y EQUIPO EN ALMACENAMIENTO: El pollo debe estar fechado con los datos de la inyección y de vencimiento para la adecuada rotación. Las bolsas de pollo deben mantenerse cerrad... | GS1: Puntos: MANEJO DE POLLO CRUDO Y EQUIPO EN ALMACENAMIENTO: El pollo debe estar fechado con los datos de la inyección y de vencimiento para la adecuada rotación. Las bolsas de pollo deben mantenerse cerrad... | GT1: Comentarios: MANEJO DE POLLO CRUDO Y EQUIPO EN ALMACENAMIENTO: El pollo debe estar fechado con los datos de la inyección y de vencimiento para la adecuada rotación. Las bolsas de pollo deben mantenerse cerrad... | GU1: Comentarios pregunta #65: | GV1: Puntos: Comentarios pregunta #65: | GW1: Comentarios: Comentarios pregunta #65: | GX1: PROCEDIMIENTO DE MANEJO DE POLLO CRUDO: Cuentan con los utensilios amarillos para la manipulación de pollo crudo (delantal, tabla, cuchillo). Se realiza el procedimiento de desinfección de las sup... | GY1: Puntos: PROCEDIMIENTO DE MANEJO DE POLLO CRUDO: Cuentan con los utensilios amarillos para la manipulación de pollo crudo (delantal, tabla, cuchillo). Se realiza el procedimiento de desinfección de las sup... | GZ1: Comentarios: PROCEDIMIENTO DE MANEJO DE POLLO CRUDO: Cuentan con los utensilios amarillos para la manipulación de pollo crudo (delantal, tabla, cuchillo). Se realiza el procedimiento de desinfección de las sup... | HA1: Comentarios pregunta #67: | HB1: Puntos: Comentarios pregunta #67: | HC1: Comentarios: Comentarios pregunta #67: | HD1: AREA DE ALMACENAMIENTO DE VEGETALES: Estantes en buen estado y canastas limpias. No se identifican vegetales en estado de deterioro o descomposición. | HE1: Puntos: AREA DE ALMACENAMIENTO DE VEGETALES: Estantes en buen estado y canastas limpias. No se identifican vegetales en estado de deterioro o descomposición. | HF1: Comentarios: AREA DE ALMACENAMIENTO DE VEGETALES: Estantes en buen estado y canastas limpias. No se identifican vegetales en estado de deterioro o descomposición. | HG1: Comentarios pregunta #69: | HH1: Puntos: Comentarios pregunta #69: | HI1: Comentarios: Comentarios pregunta #69: | HJ1: BODEGA DE ALMACENAMIENTO: se encuentra cerrada, limpia y ordenada. Estantes en buen estado. Los alimentos y material de empaque se colocan mínimo a 10 cm del piso.Solo se recibe materias primas de... | HK1: Puntos: BODEGA DE ALMACENAMIENTO: se encuentra cerrada, limpia y ordenada. Estantes en buen estado. Los alimentos y material de empaque se colocan mínimo a 10 cm del piso.Solo se recibe materias primas de... | HL1: Comentarios: BODEGA DE ALMACENAMIENTO: se encuentra cerrada, limpia y ordenada. Estantes en buen estado. Los alimentos y material de empaque se colocan mínimo a 10 cm del piso.Solo se recibe materias primas de... | HM1: Comentarios pregunta #71: | HN1: Puntos: Comentarios pregunta #71: | HO1: Comentarios: Comentarios pregunta #71: | HP1: PCC CONTAMINACION CRUZADA: Existe algún peligro de contaminación cruzada o riesgo de cuerpos extraños por contaminación física, química o microbiológica, tanto en procesos de elaboración como alma... | HQ1: Puntos: PCC CONTAMINACION CRUZADA: Existe algún peligro de contaminación cruzada o riesgo de cuerpos extraños por contaminación física, química o microbiológica, tanto en procesos de elaboración como alma... | HR1: Comentarios: PCC CONTAMINACION CRUZADA: Existe algún peligro de contaminación cruzada o riesgo de cuerpos extraños por contaminación física, química o microbiológica, tanto en procesos de elaboración como alma... | HS1: Comentarios pregunta #73: | HT1: Puntos: Comentarios pregunta #73: | HU1: Comentarios: Comentarios pregunta #73: | HV1: UNIFORME: Uniforme limpio y completo. El uniforme no se trae puesto desde la casa (autorizado pantalón y zapatos)*Calzado limpio y cerrado. La malla cubre todo el cabello, hasta las orejas. Se cu... | HW1: Puntos: UNIFORME: Uniforme limpio y completo. El uniforme no se trae puesto desde la casa (autorizado pantalón y zapatos)*Calzado limpio y cerrado. La malla cubre todo el cabello, hasta las orejas. Se cu... | HX1: Comentarios: UNIFORME: Uniforme limpio y completo. El uniforme no se trae puesto desde la casa (autorizado pantalón y zapatos)*Calzado limpio y cerrado. La malla cubre todo el cabello, hasta las orejas. Se cu... | HY1: Comentarios pregunta #75: | HZ1: Puntos: Comentarios pregunta #75: | IA1: Comentarios: Comentarios pregunta #75: | IB1: USO DE CELULAR: No se identifican celulares en uso en áreas de proceso e intermedio. Solamente el personal administrativo cuenta con autorización de uso de teléfono celular en horas laborales. | IC1: Puntos: USO DE CELULAR: No se identifican celulares en uso en áreas de proceso e intermedio. Solamente el personal administrativo cuenta con autorización de uso de teléfono celular en horas laborales. | ID1: Comentarios: USO DE CELULAR: No se identifican celulares en uso en áreas de proceso e intermedio. Solamente el personal administrativo cuenta con autorización de uso de teléfono celular en horas laborales. | IE1: Comentarios pregunta #77: | IF1: Puntos: Comentarios pregunta #77: | IG1: Comentarios: Comentarios pregunta #77: | IH1: BAÑO DE COLABORADORES Y AREA DE LOCKERS: Areas limpias y ordenadas. No se almacenan artículos en des uso. Mueble de lockers en buen estado sin etiquetas adhesivas colocadas (No personalizados). ... | II1: Puntos: BAÑO DE COLABORADORES Y AREA DE LOCKERS: Areas limpias y ordenadas. No se almacenan artículos en des uso. Mueble de lockers en buen estado sin etiquetas adhesivas colocadas (No personalizados). ... | IJ1: Comentarios: BAÑO DE COLABORADORES Y AREA DE LOCKERS: Areas limpias y ordenadas. No se almacenan artículos en des uso. Mueble de lockers en buen estado sin etiquetas adhesivas colocadas (No personalizados). ... | IK1: Comentarios pregunta #79: | IL1: Puntos: Comentarios pregunta #79: | IM1: Comentarios: Comentarios pregunta #79: | IN1: MANEJO DE ALIMENTOS Y ARTICULOS DE COLABORADORES: Se destina un espacio para el almacenamiento de comida de colaboradores. No se identifican alimentos u artículos personales de colaboradores en la... | IO1: Puntos: MANEJO DE ALIMENTOS Y ARTICULOS DE COLABORADORES: Se destina un espacio para el almacenamiento de comida de colaboradores. No se identifican alimentos u artículos personales de colaboradores en la... | IP1: Comentarios: MANEJO DE ALIMENTOS Y ARTICULOS DE COLABORADORES: Se destina un espacio para el almacenamiento de comida de colaboradores. No se identifican alimentos u artículos personales de colaboradores en la... | IQ1: Comentarios pregunta #81: | IR1: Puntos: Comentarios pregunta #81: | IS1: Comentarios: Comentarios pregunta #81: | IT1: PROVEEDORES: Proveedor sigue las reglas Rosti al ingresar al local. Uso de redecilla o gorra para el cabello. Aplica para proveedores (materias primas, mantenimiento, TI), visitas, y repartidores. | IU1: Puntos: PROVEEDORES: Proveedor sigue las reglas Rosti al ingresar al local. Uso de redecilla o gorra para el cabello. Aplica para proveedores (materias primas, mantenimiento, TI), visitas, y repartidores. | IV1: Comentarios: PROVEEDORES: Proveedor sigue las reglas Rosti al ingresar al local. Uso de redecilla o gorra para el cabello. Aplica para proveedores (materias primas, mantenimiento, TI), visitas, y repartidores. | IW1: Comentarios pregunta #83: | IX1: Puntos: Comentarios pregunta #83: | IY1: Comentarios: Comentarios pregunta #83: | IZ1: PRODUCTOS QUIMICOS: Se cuenta con los productos químicos, equipos de limpieza y desinfección necesarios, aprobados, en buen estado y dentro de su vida útil. Los mismos almacenados bajo llave lejo... | JA1: Puntos: PRODUCTOS QUIMICOS: Se cuenta con los productos químicos, equipos de limpieza y desinfección necesarios, aprobados, en buen estado y dentro de su vida útil. Los mismos almacenados bajo llave lejo... | JB1: Comentarios: PRODUCTOS QUIMICOS: Se cuenta con los productos químicos, equipos de limpieza y desinfección necesarios, aprobados, en buen estado y dentro de su vida útil. Los mismos almacenados bajo llave lejo... | JC1: Comentarios pregunta #85: | JD1: Puntos: Comentarios pregunta #85: | JE1: Comentarios: Comentarios pregunta #85: | JF1: EQUIPO DE INOCUIDAD: Disponible, en buen estado y funcionando correctamente (Kit de cloro residual, cinta de medición de sanitizante, tabla de medición del aceite, timer) | JG1: Puntos: EQUIPO DE INOCUIDAD: Disponible, en buen estado y funcionando correctamente (Kit de cloro residual, cinta de medición de sanitizante, tabla de medición del aceite, timer) | JH1: Comentarios: EQUIPO DE INOCUIDAD: Disponible, en buen estado y funcionando correctamente (Kit de cloro residual, cinta de medición de sanitizante, tabla de medición del aceite, timer) | JI1: Comentarios pregunta #87: | JJ1: Puntos: Comentarios pregunta #87: | JK1: Comentarios: Comentarios pregunta #87: | JL1: AGUAS RESIDUALES: Trampas de grasa y rhinos en buen estado y con evidencia de limpieza frecuente. El rhino cuenta con malla bien colocada y en buen estado, pilas y drenajes de piso cuentan con re... | JM1: Puntos: AGUAS RESIDUALES: Trampas de grasa y rhinos en buen estado y con evidencia de limpieza frecuente. El rhino cuenta con malla bien colocada y en buen estado, pilas y drenajes de piso cuentan con re... | JN1: Comentarios: AGUAS RESIDUALES: Trampas de grasa y rhinos en buen estado y con evidencia de limpieza frecuente. El rhino cuenta con malla bien colocada y en buen estado, pilas y drenajes de piso cuentan con re... | JO1: Comentarios pregunta #89: | JP1: Puntos: Comentarios pregunta #89: | JQ1: Comentarios: Comentarios pregunta #89: | JR1: MANEJO INTEGRADO DE PLAGAS: Se identifica actividad de plagas (insectos, roedores, etc). Se evidencian de manera visible o hay rastros de presencia de los mismos en el local. En caso positivo, hay... | JS1: Puntos: MANEJO INTEGRADO DE PLAGAS: Se identifica actividad de plagas (insectos, roedores, etc). Se evidencian de manera visible o hay rastros de presencia de los mismos en el local. En caso positivo, hay... | JT1: Comentarios: MANEJO INTEGRADO DE PLAGAS: Se identifica actividad de plagas (insectos, roedores, etc). Se evidencian de manera visible o hay rastros de presencia de los mismos en el local. En caso positivo, hay... | JU1: Comentarios pregunta #91: | JV1: Puntos: Comentarios pregunta #91: | JW1: Comentarios: Comentarios pregunta #91: | JX1: REGISTRO DE COCCION DE POLLO: Los registro de cocción de pollo se encuentra completo, al día (hasta la última desmonta del pollo), ordenado y verificado (mínimo una vez por semana). Cumplimiento d... | JY1: Puntos: REGISTRO DE COCCION DE POLLO: Los registro de cocción de pollo se encuentra completo, al día (hasta la última desmonta del pollo), ordenado y verificado (mínimo una vez por semana). Cumplimiento d... | JZ1: Comentarios: REGISTRO DE COCCION DE POLLO: Los registro de cocción de pollo se encuentra completo, al día (hasta la última desmonta del pollo), ordenado y verificado (mínimo una vez por semana). Cumplimiento d... | KA1: Comentarios pregunta #93: | KB1: Puntos: Comentarios pregunta #93: | KC1: Comentarios: Comentarios pregunta #93: | KD1: COMENTARIOS ADICIONALES: | KE1: Puntos: COMENTARIOS ADICIONALES: | KF1: Comentarios: COMENTARIOS ADICIONALES:
A2: 1 | B2: 45061.437 | C2: 45061.438 | D2: anonymous | F2: 29 | H2: Coronado | K2: 45061 | N2: prueba | Q2: Nazira Herrera | T2: Cumple | U2: 2 | Z2: Cumple | AA2: 2 | AF2: Cumple | AG2: 2 | AM2: 0 | AS2: 0 | AY2: 0 | BE2: 0 | BK2: 0 | BP2: Cumple | BQ2: 3 | BV2: Cumple | BW2: 2 | CC2: 0 | CH2: Cumple | CI2: 2 | CN2: Cumple | CO2: 2 | CU2: 0 | CZ2: Cumple | DA2: 2 | DF2: Cumple | DG2: 2 | DL2: Cumple | DM2: 3 | DR2: Cumple | DS2: 3 | DX2: No cumple | DY2: 0 | EE2: 0 | EJ2: No cumple | EK2: 0 | EP2: No cumple | EQ2: 0 | EW2: 0 | FB2: No cumple | FC2: 0 | FH2: No cumple | FI2: 0 | FN2: No cumple | FO2: 0 | FT2: Cumple | FU2: 2 | FZ2: No cumple | GA2: 0 | GF2: No cumple | GG2: 0 | GL2: No cumple | GM2: 0 | GR2: Cumple | GS2: 2 | GY2: 0 | HE2: 0 | HK2: 0 | HQ2: 0 | HW2: 0 | IC2: 0 | II2: 0 | IO2: 0 | IU2: 0 | JA2: 0 | JG2: 0 | JM2: 0 | JS2: 0 | JY2: 0
A3: 2 | B3: 45061.44 | C3: 45061.442 | D3: anonymous | F3: 32 | H3: City Mall | K3: 45061 | N3: prueba | Q3: Nazira Herrera | T3: Cumple | U3: 2 | Z3: Cumple | AA3: 2 | AF3: Cumple | AG3: 2 | AM3: 0 | AS3: 0 | AY3: 0 | BE3: 0 | BK3: 0 | BP3: No cumple | BQ3: 0 | BV3: Cumple | BW3: 2 | CC3: 0 | CH3: Cumple | CI3: 2 | CN3: Cumple | CO3: 2 | CU3: 0 | CZ3: Cumple | DA3: 2 | DF3: No cumple | DG3: 0 | DL3: Cumple | DM3: 3 | DR3: No cumple | DS3: 0 | DX3: Cumple | DY3: 3 | EE3: 0 | EJ3: Cumple | EK3: 2 | EP3: Cumple | EQ3: 2 | EW3: 0 | FB3: Cumple | FC3: 2 | FH3: Cumple | FI3: 2 | FN3: No cumple | FO3: 0 | FT3: No cumple | FU3: 0 | FZ3: No cumple | GA3: 0 | GF3: Cumple | GG3: 2 | GL3: Cumple | GM3: 2 | GR3: No cumple | GS3: 0 | GY3: 0 | HE3: 0 | HK3: 0 | HQ3: 0 | HW3: 0 | IC3: 0 | II3: 0 | IO3: 0 | IU3: 0 | JA3: 0 | JG3: 0 | JM3: 0 | JS3: 0 | JY3: 0
A4: 3 | B4: 45061.449 | C4: 45061.456 | D4: anonymous | F4: 27 | H4: Coronado | K4: 45061 | N4: prueba | Q4: Nazira Herrera | T4: Cumple | U4: 2 | Z4: Cumple | AA4: 2 | AF4: Cumple | AG4: 2 | AM4: 0 | AS4: 0 | AY4: 0 | BE4: 0 | BK4: 0 | BP4: Cumple | BQ4: 3 | BV4: Cumple | BW4: 2 | CC4: 0 | CH4: Cumple | CI4: 2 | CN4: No cumple | CO4: 0 | CU4: 0 | CZ4: No cumple | DA4: 0 | DF4: No cumple | DG4: 0 | DL4: No cumple | DM4: 0 | DR4: Cumple | DS4: 3 | DX4: Cumple | DY4: 3 | EE4: 0 | EJ4: Cumple | EK4: 2 | EP4: No cumple | EQ4: 0 | EW4: 0 | FB4: No cumple | FC4: 0 | FH4: Cumple | FI4: 2 | FN4: No cumple | FO4: 0 | FT4: No cumple | FU4: 0 | FZ4: No cumple | GA4: 0 | GF4: Cumple | GG4: 2 | GL4: Cumple | GM4: 2 | GR4: No cumple | GS4: 0 | GY4: 0 | HE4: 0 | HK4: 0 | HQ4: 0 | HW4: 0 | IC4: 0 | II4: 0 | IO4: 0 | IU4: 0 | JA4: 0 | JG4: 0 | JM4: 0 | JS4: 0 | JY4: 0
A5: 4 | B5: 45062.619 | C5: 45062.64 | D5: anonymous | F5: 42 | H5: Curridabat | K5: 45062 | N5: Dayanna Trejos Chavez | Q5: Maura Osegueda | T5: Cumple | U5: 2 | Z5: Cumple | AA5: 2 | AF5: No cumple | AG5: 0 | AI5: No se había llenado la información de la segunda monta hasta el momento que se le pidió el registro y se hizo la desmonta sin pedir el registro. | AM5: 0 | AS5: 0 | AY5: 0 | BE5: 0 | BK5: 0 | BP5: Cumple | BQ5: 3 | BV5: Cumple | BW5: 2 | CC5: 0 | CH5: Cumple | CI5: 2 | CN5: Cumple | CO5: 2 | CU5: 0 | CZ5: Cumple | DA5: 2 | DF5: Cumple | DG5: 2 | DL5: Cumple | DM5: 3 | DR5: Cumple | DS5: 3 | DX5: Cumple | DY5: 3 | EE5: 0 | EJ5: No cumple | EK5: 0 | EM5: Se encuentra varios puntos con fechas incorrectas: -Limonada con fechas vencidas -Cebollitas picantes en el mostrador vencidas. -Envaces con fecha erróneas. | EP5: Cumple | EQ5: 2 | EW5: 0 | FB5: Cumple | FC5: 2 | FH5: Cumple | FI5: 2 | FN5: Cumple | FO5: 2 | FT5: Cumple | FU5: 2 | FZ5: No cumple | GA5: 0 | GC5: Se encuentra con productos que no son postres lo cual no se ve bonito para los ojos de los clientes. | GF5: Cumple | GG5: 2 | GL5: Cumple | GM5: 2 | GR5: Cumple | GS5: 2 | GY5: 0 | HE5: 0 | HK5: 0 | HQ5: 0 | HW5: 0 | IC5: 0 | II5: 0 | IO5: 0 | IU5: 0 | JA5: 0 | JG5: 0 | JM5: 0 | JS5: 0 | JY5: 0
A6: 5 | B6: 45062.793 | C6: 45062.799 | D6: anonymous | F6: 44 | H6: San José | K6: 45062 | N6: Diana | Q6: Heidi Murillo | T6: Cumple | U6: 2 | W6: Cumple | Z6: Cumple | AA6: 2 | AC6: Cumple | AF6: Cumple | AG6: 2 | AI6: Cumple | AM6: 0 | AS6: 0 | AY6: 0 | BE6: 0 | BK6: 0 | BP6: Cumple | BQ6: 3 | BS6: Cumple | BV6: Cumple | BW6: 2 | CC6: 0 | CE6: Cumple | CH6: Cumple | CI6: 2 | CK6: Cumple | CN6: Cumple | CO6: 2 | CQ6: Cumple | CU6: 0 | CZ6: No cumple | DA6: 0 | DC6: No se respeta el código de color por áreas y utilizan paños amarillos para limpieza profunda en salón y pila. | DF6: Cumple | DG6: 2 | DI6: Cumple | DL6: Cumple | DM6: 3 | DO6: Cumple | DR6: Cumple | DS6: 3 | DU6: Cumple | DX6: Cumple | DY6: 3 | EA6: Cumple | EE6: 0 | EJ6: Cumple | EK6: 2 | EM6: Cumple | EP6: Cumple | EQ6: 2 | ES6: Cumple | EW6: 0 | FB6: Cumple | FC6: 2 | FE6: Cumple | FH6: Cumple | FI6: 2 | FK6: Cumple | FN6: Cumple | FO6: 2 | FQ6: Cumple | FT6: No cumple | FU6: 0 | FW6: Se encuentran una bolsa de strips mal fechada con 2 dias de vida útil y una bolsa de chicharrón con 4 dias de vida útil, se les hace la corrección. | FZ6: Cumple | GA6: 2 | GC6: Cumple | GF6: Cumple | GG6: 2 | GI6: Cumple | GL6: Cumple | GM6: 2 | GO6: Cumple | GR6: Cumple | GS6: 2 | GY6: 0 | HE6: 0 | HK6: 0 | HQ6: 0 | HW6: 0 | IC6: 0 | II6: 0 | IO6: 0 | IU6: 0 | JA6: 0 | JG6: 0 | JM6: 0 | JS6: 0 | JY6: 0 | KD6: Mantener mucho cuidado cuando se despachan los platillos porque se visualizan cucarachas en la cocina, se recomienda no descuidar la limpieza del segundo piso, principalmente por el área del monta cargas.
A7: 6 | B7: 45065.531 | C7: 45065.553 | D7: anonymous | F7: 44 | H7: FC Pueblo Antiguo | K7: 45065 | N7: Henry Hernàndez | Q7: Nazira Herrera | T7: Cumple | U7: 2 | W7: Se recomienda descartar termómetro con carátula en mal estado, poco legible. | Z7: No Cumple | AA7: 0 | AF7: Cumple | AG7: 2 | AM7: 0 | AS7: 0 | AY7: 0 | BE7: 0 | BK7: 0 | BP7: Cumple | BQ7: 3 | BV7: Cumple | BW7: 2 | CC7: 0 | CH7: Cumple | CI7: 2 | CN7: Cumple | CO7: 2 | CQ7: Cintas de medición vencidas 2019. Reciben nuevas 2025 durante la visita. | CU7: 0 | CZ7: Cumple | DA7: 2 | DF7: Cumple | DG7: 2 | DL7: Cumple | DM7: 3 | DR7: Cumple | DS7: 3 | DX7: Cumple | DY7: 3 | EE7: 0 | EJ7: No cumple | EK7: 0 | EM7: Empanadas no se encuentran identificadas por producto. | EP7: Cumple | EQ7: 2 | EW7: 0 | FB7: Cumple | FC7: 2 | FH7: Cumple | FI7: 2 | FN7: Cumple | FO7: 2 | FT7: Cumple | FU7: 2 | FZ7: Cumple | GA7: 2 | GF7: Cumple | GG7: 2 | GL7: Cumple | GM7: 2 | GR7: Cumple | GS7: 2 | GY7: 0 | HE7: 0 | HK7: 0 | HQ7: 0 | HW7: 0 | IC7: 0 | II7: 0 | IO7: 0 | IU7: 0 | JA7: 0 | JG7: 0 | JM7: 0 | JS7: 0 | JY7: 0
A8: 7 | B8: 45065.878 | C8: 45065.887 | D8: anonymous | F8: 41 | H8: Escazú | K8: 45065 | N8: Doris | Q8: Heidi Murillo | T8: Cumple | U8: 2 | W8: Cumple | Z8: Cumple | AA8: 2 | AC8: No se visualiza riesgo | AF8: No cumple | AG8: 0 | AI8: No se respeta la vida útil del pollo y Pechugas de 3 horas en las montas del 5 y 9 y de 6 horas del 2,3,5 y 9 y registros incompletos los días 7,14 y 17 | AM8: 0 | AS8: 0 | AY8: 0 | BE8: 0 | BK8: 0 | BP8: No cumple | BQ8: 0 | BS8: Masa y empanizador reempacados sin fecha de vencimiento. | BV8: Cumple | BW8: 2 | CC8: 0 | CE8: Cumple | CH8: Cumple | CI8: 2 | CK8: Cumple | CN8: Cumple | CO8: 2 | CQ8: Cumple | CU8: 0 | CZ8: Cumple | DA8: 2 | DC8: Se recomienda cambiar 2 paños verdes de cocina muy deteriorados | DF8: Cumple | DG8: 2 | DI8: Detallar un poquito la limpieza de la cachera del lavamanos | DL8: Cumple | DM8: 3 | DO8: Cumple | DR8: Cumple | DS8: 3 | DU8: Cumple | DX8: Cumple | DY8: 3 | EA8: Cumple | EE8: 0 | EJ8: Cumple | EK8: 2 | EM8: Cumple | EP8: Cumple | EQ8: 2 | ES8: Cumple | EW8: 0 | FB8: Cumple | FC8: 2 | FE8: Cumple | FH8: Cumple | FI8: 2 | FK8: Cumple | FN8: Cumple | FO8: 2 | FQ8: Cumple | FT8: No cumple | FU8: 0 | FW8: Chicharrón de pollo mal fechado con 4 días de vida útil y son sólo 2 días. | FZ8: Cumple | GA8: 2 | GC8: Cumple | GF8: Cumple | GG8: 2 | GI8: Cumple | GL8: Cumple | GM8: 2 | GO8: Cumple | GR8: Cumple | GS8: 2 | GY8: 0 | HE8: 0 | HK8: 0 | HQ8: 0 | HW8: 0 | IC8: 0 | II8: 0 | IO8: 0 | IU8: 0 | JA8: 0 | JG8: 0 | JM8: 0 | JS8: 0 | JY8: 0 | KD8: Se recomienda revisar con el equipo administrativo las oportunidades que se conversaron respecto a los registros de temperatura y monta del pollo. No obstante se nota una mejoría en el orden y la limpieza, se les agradece el esfuerzo y se les insta a seguir trabajando en mejorar.
A9: 8 | B9: 45066.556 | C9: 45066.569 | D9: anonymous | F9: 36 | H9: Sabana | K9: 45066 | N9: Edwin | Q9: Heidi Murillo | T9: Cumple | U9: 2 | W9: Cumple | Z9: Cumple | AA9: 2 | AC9: Cumple no se visualiza ningún riesgo | AF9: Cumple | AG9: 2 | AI9: Cumple | AM9: 0 | AS9: 0 | AY9: 0 | BE9: 0 | BK9: 0 | BP9: No cumple | BQ9: 0 | BS9: El empanizador reempacado estaba sin fecha de vencimiento. | BV9: Cumple | BW9: 2 | CC9: 0 | CE9: Cumple | CH9: Cumple | CI9: 2 | CK9: Cumple, revisar el pedal porque no está funcionando correctamente. | CN9: No cumple | CO9: 0 | CQ9: Cinta de medir el sanitizante vencida desde Nov 2018. | CU9: 0 | CZ9: No cumple | DA9: 0 | DC9: Paños de cocina y pollo los mantienen sobre las mesas de trabajo y no en solución sanitizante. | DF9: No cumple | DG9: 0 | DI9: Se encuentra alimentos de colaboradores fuera de la caja destinada para este fin. Cereales en el express | DL9: Cumple | DM9: 3 | DO9: Cumple | DR9: No cumple | DS9: 0 | DU9: Reforzar la limpieza del area frente a la puerta de empleados, estaba muy desordenada con cajas y había un indigente durmiendo ahí. | DX9: Cumple | DY9: 3 | EA9: Cumple | EE9: 0 | EJ9: Cumple | EK9: 2 | EM9: Cumple | EP9: Cumple | EQ9: 2 | ES9: Cumple | EW9: 0 | FB9: Cumple | FC9: 2 | FE9: Cumple | FH9: Cumple | FI9: 2 | FK9: Cumple | FN9: Cumple | FO9: 2 | FQ9: Cumple | FT9: Cumple | FU9: 2 | FW9: Cumple | FZ9: Cumple | GA9: 2 | GC9: Cumple | GF9: Cumple | GG9: 2 | GI9: Cumple | GL9: Cumple | GM9: 2 | GO9: Cumple | GR9: Cumple | GS9: 2 | GY9: 0 | HE9: 0 | HK9: 0 | HQ9: 0 | HW9: 0 | IC9: 0 | II9: 0 | IO9: 0 | IU9: 0 | JA9: 0 | JG9: 0 | JM9: 0 | JS9: 0 | JY9: 0 | KD9: Se notan avances importantes en limpieza, se les insta a seguir trabajando para mejorar las oportunidades conversadas. Gracias por el esfuerzo que están realizando.
A10: 9 | B10: 45067.575 | C10: 45067.582 | D10: anonymous | F10: 44 | H10: Real Alajuela | K10: 45067 | N10: Sergio | Q10: Heidi Murillo | T10: Cumple | U10: 2 | W10: Cumple | Z10: Cumple | AA10: 2 | AC10: No se visualiza ningún riesgo materializable | AF10: Cumple | AG10: 2 | AI10: Cumple, se conversa con el gerente sobre revisar la exactitud en las horas de monta y desmonta. | AM10: 0 | AS10: 0 | AY10: 0 | BE10: 0 | BK10: 0 | BP10: Cumple | BQ10: 3 | BS10: Cumple | BV10: Cumple | BW10: 2 | CC10: 0 | CE10: Cumple | CH10: Cumple | CI10: 2 | CN10: Cumple | CO10: 2 | CQ10: Cumple | CU10: 0 | CZ10: Cumple | DA10: 2 | DC10: Cumple | DF10: No cumple | DG10: 0 | DI10: Bolso de colaboradora fuera de lockers y pan de colaboradores en estante de la cocina. | DL10: Cumple | DM10: 3 | DO10: Cumple, se recomienda pedir una tapa reducida para el basurero de la pila. | DR10: Cumple | DS10: 3 | DU10: Cumple | DX10: Cumple | DY10: 3 | EA10: Cumple | EE10: 0 | EJ10: No cumple | EK10: 0 | EM10: Chicarrón de pollo sin fechar y tortilla aliñada con fecha equivocada. | EP10: Cumple | EQ10: 2 | ES10: Cumple | EW10: 0 | FB10: Cumple | FC10: 2 | FE10: Cumple | FH10: Cumple | FI10: 2 | FK10: Cumple | FN10: Cumple | FO10: 2 | FQ10: Cumple | FT10: Cumple | FU10: 2 | FZ10: Cumple | GA10: 2 | GC10: Cumple | GF10: Cumple | GG10: 2 | GL10: Cumple | GM10: 2 | GO10: Cumple | GR10: Cumple | GS10: 2 | GY10: 0 | HE10: 0 | HK10: 0 | HQ10: 0 | HW10: 0 | IC10: 0 | II10: 0 | IO10: 0 | IU10: 0 | JA10: 0 | JG10: 0 | JM10: 0 | JS10: 0 | JY10: 0 | KD10: Muchas gracias por la constancia y el seguimiento de la oportunidad es conversadas.
A11: 10 | B11: 45069.886 | C11: 45069.9 | D11: anonymous | F11: 36 | H11: Lincoln | K11: 45069 | N11: Andrea Rojas | Q11: Heidi Murillo | T11: No cumple | U11: 0 | W11: No encuentran el termómetro del freidor, no se logró evaluar. El termómetro de pollo estaba correctamente. | Z11: No Cumple | AA11: 0 | AC11: La colaboradora Dayana estaba deshuesando las pechugas sin guantes, el caldo de pollo lo tenían enfriando en la pila y le estaba cayendo el agua que escurría de las bandejas colocadas en el estante superior. Se le recomendó a la encargada desechar ese producto. | AF11: No cumple | AG11: 0 | AI11: Faltan algunos datos del 18 y algunos registros estaban con fechas incorrectas, lo que hace que pierdan validez (por ejemplo tenían datos de montas con fecha del 24 y apenas hoy es 23) | AM11: 0 | AS11: 0 | AY11: 0 | BE11: 0 | BK11: 0 | BP11: Cumple | BQ11: 3 | BS11: Mejorar la limpieza del piso. | BV11: Cumple | BW11: 2 | CC11: 0 | CE11: Cumple | CH11: No cumple | CI11: 0 | CK11: Lavamanos muy sucio, con residuos de servilletas y papel. | CN11: Cumple | CO11: 2 | CQ11: Cumple | CU11: 0 | CZ11: Cumple | DA11: 2 | DC11: Cumple | DF11: Cumple | DG11: 2 | DI11: Cumple | DL11: Cumple | DM11: 3 | DO11: El basurero de cocina estaba con la tapa muy sucia, llena de tizne como si le hubiesen puesto una olla encima. | DR11: Cumple | DS11: 3 | DU11: Cumple | DX11: Cumple | DY11: 3 | EA11: Cumple | EE11: 0 | EJ11: Cumple | EK11: 2 | EM11: Cumple | EP11: Cumple | EQ11: 2 | ES11: Cumple | EW11: 0 | FB11: Cumple | FC11: 2 | FE11: Cumple | FH11: No cumple | FI11: 0 | FK11: No se respeta el tiempo de enfriamiento. Tenían pasta de pollo y caldo de pollo con muchas horas, con el hielo derretido y el agua del mismo a temperatura ambiente. | FN11: Cumple | FO11: 2 | FQ11: Cumple | FT11: No cumple | FU11: 0 | FW11: El piso detrás de la cámara estaba muy sucio y como había un olor a podrido se procedió a revisar el área y se encontró la bandeja con con residuos en estado de descomposición, se les pidió que la lavaran. | FZ11: Cumple | GA11: 2 | GC11: Cumple | GF11: Cumple | GG11: 2 | GI11: Cumple | GL11: Cumple | GM11: 2 | GO11: Cumple | GR11: Cumple | GS11: 2 | GY11: 0 | HE11: 0 | HK11: 0 | HQ11: 0 | HW11: 0 | IC11: 0 | II11: 0 | IO11: 0 | IU11: 0 | JA11: 0 | JG11: 0 | JM11: 0 | JS11: 0 | JY11: 0 | KD11: Urge revisar las oportunidades evidenciadas. Muchas oportunidades de limpieza.
A12: 11 | B12: 45072.608 | C12: 45072.628 | D12: anonymous | F12: 38 | H12: Multiplaza Curridabat | K12: 45072 | N12: Alejandra Granados | Q12: Nazira Herrera | T12: Cumple | U12: 2 | Z12: No Cumple | AA12: 0 | AF12: No cumple | AG12: 0 | AI12: Hay información ilegible, datos tachados y uso de lápiz en el registro. | AM12: 0 | AS12: 0 | AY12: 0 | BE12: 0 | BK12: 0 | BP12: Cumple | BQ12: 3 | BV12: No cumple | BW12: 0 | CC12: 0 | CE12: Colaboradora de cocina con contacto directo con alimentos utiliza pulsera plástica. | CH12: Cumple | CI12: 2 | CN12: Cumple | CO12: 2 | CU12: 0 | CZ12: Cumple | DA12: 2 | DF12: No cumple | DG12: 0 | DI12: Falta mejorar orden del área de locker, no mantener uniformes sobre los muebles. | DL12: Cumple | DM12: 3 | DR12: Cumple | DS12: 3 | DX12: Cumple | DY12: 3 | EE12: 0 | EJ12: Cumple | EK12: 2 | EP12: Cumple | EQ12: 2 | EW12: 0 | FB12: Cumple | FC12: 2 | FH12: Cumple | FI12: 2 | FN12: Cumple | FO12: 2 | FT12: Cumple | FU12: 2 | FZ12: No cumple | GA12: 0 | GC12: Retirar flores deterioradas y marchitas de postres y urna | GF12: Cumple | GG12: 2 | GL12: Cumple | GM12: 2 | GR12: Cumple | GS12: 2 | GY12: 0 | HE12: 0 | HK12: 0 | HQ12: 0 | HW12: 0 | IC12: 0 | II12: 0 | IO12: 0 | IU12: 0 | JA12: 0 | JG12: 0 | JM12: 0 | JS12: 0 | JY12: 0 | KD12: Muchas mejoras en orden y limpieza de equipos. Excelente el área de servicio y atención a clientes. El área de preparación siempre se mantiene muy incomoda. Evaluar sustitución de pila por mesa de pollo cocinado o soporte para enfriamiento de alimentos etc.
A13: 12 | B13: 45074.581 | C13: 45074.594 | D13: anonymous | F13: 37 | H13: Coronado | K13: 45074 | N13: Graciela | Q13: Heidi Murillo | T13: Cumple | U13: 2 | W13: El termómetro del freidor no está funcionando correctamente, porque se hace prueba y no está censando bien la temperatura, no llegó ni a los 300 F. Se recomienda cambiarlo. | Z13: Cumple | AA13: 2 | AC13: Cumple | AF13: Cumple | AG13: 2 | AI13: Cumple | AM13: 0 | AS13: 0 | AY13: 0 | BE13: 0 | BK13: 0 | BP13: Cumple | BQ13: 3 | BS13: Cumple | BV13: Cumple | BW13: 2 | CC13: 0 | CE13: Cumple | CH13: Cumple | CI13: 2 | CK13: Cumple | CN13: Cumple | CO13: 2 | CQ13: Cumple | CU13: 0 | CZ13: Cumple | DA13: 2 | DC13: Se recomienda cambiar dos paños verde que están muy deteriorados y ya se ven muy curtidos. | DF13: No cumple | DG13: 0 | DI13: No cumple, se guardan alimentos personales en la cámara, fuera de la caja de comida de colaboradores (natilla) | DL13: No cumple | DM13: 0 | DO13: Usan el basurero interno sin tapar, le quitaron la tapa y la tenían debajo de la pila, se les hace la observación y la corrigen en el momento. | DR13: Cumple | DS13: 3 | DU13: Cumple | DX13: Cumple | DY13: 3 | EA13: Cumple | EE13: 0 | EJ13: No cumple | EK13: 0 | EM13: Se encuentra pasta de pollo en bandeja sin fechar. | EP13: Cumple | EQ13: 2 | ES13: Cumple | EW13: 0 | FB13: Cumple | FC13: 2 | FE13: Cumple | FH13: No cumple | FI13: 0 | FK13: Se encuentra Arroz blanco enfriando a temperatura ambiente, sin el procedimiento correcto. | FN13: Cumple | FO13: 2 | FQ13: Cumple | FT13: No cumple | FU13: 0 | FW13: Cámara de pollo muy sucia por fuera, las puertas llenas de residuos de bater y empanizador. | FZ13: Cumple | GA13: 2 | GC13: Cumple | GF13: Cumple | GG13: 2 | GI13: Cumple | GL13: Cumple | GM13: 2 | GO13: Cumple | GR13: Cumple | GS13: 2 | GY13: 0 | HE13: 0 | HK13: 0 | HQ13: 0 | HW13: 0 | IC13: 0 | II13: 0 | IO13: 0 | IU13: 0 | JA13: 0 | JG13: 0 | JM13: 0 | JS13: 0 | JY13: 0 | KD13: Revisar y trabajar en las oportunidades conversadas.
