Workbook
Name FechaFinal: Parámetros!$G$4
Name FechaInicial: Parámetros!$G$3

Sheet Parámetros
C2: DD/MM/ANO
B3: Fecha Inicio | C3: 46023 | G3: =TEXT(_xlfn.CONCAT(YEAR(C3),"-",MONTH(C3),"-",DAY(C3)),"aaaa-mm-dd") -> 2026-01-01
B4: Fecha Final | C4: =TODAY()-1 -> 46065 | G4: =TEXT(_xlfn.CONCAT(YEAR(C4),"-",MONTH(C4),"-",DAY(C4)),"aaaa-mm-dd") -> 2026-02-12
B6: KPI | C6: Ventas
B8: Mal
B9: Bien | C9: -0.05
B10: Muy Bien | C10: -0.01

Sheet Evaluación
A1: =+Parámetros!C4 -> 46065
C2: Total | I2: Salón | O2: Llevar | U2: AutoPollo | AA2: Express | AG2: UberEats | AM2: ECommerce | AS2: Participación (Formato por canal) | BA2: Participaciones
A3: Restaurantes | B3: CREF | C3: 2025 | D3: 2026 | E3: % | F3: PRE | G3: %P | I3: =C3 -> 2025 | J3: =D3 -> 2026 | K3: % | L3: PRE | M3: %P | O3: =I3 -> 2025 | P3: =J3 -> 2026 | Q3: % | R3: PRE | S3: %P | U3: =O3 -> 2025 | V3: =P3 -> 2026 | W3: % | X3: PRE | Y3: %P | AA3: =U3 -> 2025 | AB3: =V3 -> 2026 | AC3: % | AD3: PRE | AE3: %P | AG3: =AA3 -> 2025 | AH3: =AB3 -> 2026 | AI3: % | AJ3: PRE | AK3: %P | AM3: =AG3 -> 2025 | AN3: =AH3 -> 2026 | AO3: % | AP3: PRE | AQ3: %P | AS3: Salón | AT3: Lllevar | AU3: AutoPollo | AV3: Express | AW3: UberEats | AX3: ECommerce | AY3: %
A4: Alajuela | B4: =IF(IFERROR(VLOOKUP(A4,DATA_KPI!$D:$H,5,FALSE),"")="",VLOOKUP(A4,DATA_KPI_PRE!$D:$H,5,FALSE),VLOOKUP(A4,DATA_KPI!$D:$H,5,FALSE)) -> S08 | C4: =IFERROR(VLOOKUP(_xlfn.CONCAT($C$3,"_",B4,"_",$C$2,"_",Parámetros!$C$6),DATA_KPI!$A:$H,6,FALSE),0) -> 25392157 | D4: =IFERROR(VLOOKUP(_xlfn.CONCAT($D$3,"_",B4,"_",$C$2,"_",Parámetros!$C$6),DATA_KPI!A:H,6,FALSE),0) -> 24211254 | E4: =IFERROR(+(D4/C4)-1,0) -> -0.046506602 | F4: =IFERROR(VLOOKUP(_xlfn.CONCAT($D$3,"_",B4,"_",$C$2,"_",Parámetros!$C$6),DATA_KPI_PRE!$A:$F,6,FALSE),0) -> 24973716 | G4: =IFERROR(+(D4/F4)-1,0) -> -0.030530566 | I4: =IFERROR(VLOOKUP(_xlfn.CONCAT($I$3,"_",B4,"_",$I$2,"_",Parámetros!$C$6),DATA_KPI!$A:$H,6,FALSE),0) -> 21575021 | J4: =IFERROR(VLOOKUP(_xlfn.CONCAT($J$3,"_",B4,"_",$I$2,"_",Parámetros!$C$6),DATA_KPI!$A:$H,6,FALSE),0) -> 21431430 | K4: =IFERROR(+(J4/I4)-1,0) -> -0.006655433 | L4: =IFERROR(VLOOKUP(_xlfn.CONCAT($J$3,"_",B4,"_",$I$2,"_",Parámetros!$C$6),DATA_KPI_PRE!A:F,6,FALSE),0) -> 19937031 | M4: =IFERROR(+(J4/L4)-1,0) -> 0.074955959 | O4: =IFERROR(VLOOKUP(_xlfn.CONCAT($O$3,"_",B4,"_",$O$2,"_",Parámetros!$C$6),DATA_KPI!$A:$H,6,FALSE),0) -> 1294851.6 | P4: =IFERROR(VLOOKUP(_xlfn.CONCAT($P$3,"_",B4,"_",$O$2,"_",Parámetros!$C$6),DATA_KPI!$A:$H,6,FALSE),0) -> 576962.28 | Q4: =IFERROR(+(P4/O4)-1,0) -> -0.55441823 | R4: =IFERROR(VLOOKUP(_xlfn.CONCAT($P$3,"_",B4,"_",$O$2,"_",Parámetros!$C$6),DATA_KPI_PRE!A:F,6,FALSE),0) -> 1663129.7 | S4: =IFERROR(+(P4/R4)-1,0) -> -0.65308643 | U4: =IFERROR(VLOOKUP(_xlfn.CONCAT($U$3,"_",B4,"_",$U$2,"_",Parámetros!$C$6),DATA_KPI!$A:$H,6,FALSE),0) -> 557132.88 | V4: =IFERROR(VLOOKUP(_xlfn.CONCAT($V$3,"_",B4,"_",$U$2,"_",Parámetros!$C$6),DATA_KPI!$A:$H,6,FALSE),0) -> 289283.39 | W4: =IFERROR(+(V4/U4)-1,0) -> -0.4807641 | X4: =IFERROR(VLOOKUP(_xlfn.CONCAT($V$3,"_",B4,"_",$U$2,"_",Parámetros!$C$6),DATA_KPI_PRE!A:F,6,FALSE),0) -> 574400.9 | Y4: =IFERROR(+(V4/X4)-1,0) -> -0.49637372 | AA4: =IFERROR(VLOOKUP(_xlfn.CONCAT($AA$3,"_",B4,"_",$AA$2,"_",Parámetros!$C$6),DATA_KPI!$A:$H,6,FALSE),0) -> 154931.93 | AB4: =IFERROR(VLOOKUP(_xlfn.CONCAT($AB$3,"_",B4,"_",$AA$2,"_",Parámetros!$C$6),DATA_KPI!$A:$H,6,FALSE),0) -> 334495.71 | AC4: =IFERROR(+(AB4/AA4)-1,0) -> 1.158985 | AD4: =IFERROR(VLOOKUP(_xlfn.CONCAT($AB$3,"_",B4,"_",$AA$2,"_",Parámetros!$C$6),DATA_KPI_PRE!A:F,6,FALSE),0) -> 886938.18 | AE4: =IFERROR(+(AB4/AD4)-1,0) -> -0.62286468 | AG4: =IFERROR(VLOOKUP(_xlfn.CONCAT($AG$3,"_",B4,"_",$AG$2,"_",Parámetros!$C$6),DATA_KPI!$A:$H,6,FALSE),0) -> 1624335.9 | AH4: =IFERROR(VLOOKUP(_xlfn.CONCAT($AH$3,"_",B4,"_",$AG$2,"_",Parámetros!$C$6),DATA_KPI!$A:$H,6,FALSE),0) -> 1493348.1 | AI4: =IFERROR(+(AH4/AG4)-1,0) -> -0.080640856 | AJ4: =IFERROR(VLOOKUP(_xlfn.CONCAT($AH$3,"_",B4,"_",$AG$2,"_",Parámetros!$C$6),DATA_KPI_PRE!A:F,6,FALSE),0) -> 1664044.4 | AK4: =IFERROR(+(AH4/AJ4)-1,0) -> -0.10257917 | AM4: =IFERROR(VLOOKUP(_xlfn.CONCAT($AM$3,"_",B4,"_",$AM$2,"_",Parámetros!$C$6),DATA_KPI!$A:$H,6,FALSE),0) -> 185883.47 | AN4: =IFERROR(VLOOKUP(_xlfn.CONCAT($AN$3,"_",B4,"_",$AM$2,"_",Parámetros!$C$6),DATA_KPI!$A:$H,6,FALSE),0) -> 85734.53 | AO4: =IFERROR(+AN4/AM4,0) -> 0.46122729 | AP4: =IFERROR(VLOOKUP(_xlfn.CONCAT($AN$3,"_",B4,"_",$AM$2,"_",Parámetros!$C$6),DATA_KPI_PRE!A:F,6,FALSE),0) -> 248171.78 | AQ4: =IFERROR(+(AN4/AP4)-1,0) -> -0.65453553 | AS4: =J4/D4 -> 0.88518464 | AT4: =P4/D4 -> 0.023830334 | AU4: =V4/D4 -> 0.011948302 | AV4: =AB4/D4 -> 0.013815712 | AW4: =AH4/D4 -> 0.061679914 | AX4: =AN4/D4 -> 0.0035411024 | AY4: =SUM(AS4:AX4) -> 1 | BA4: Part. V Restaurantes UBER | BB4: =(AJ30+AJ39)/AJ57 -> 0.84105396
A5: Ave. Escazú | B5: S22 | C5: =IFERROR(VLOOKUP(_xlfn.CONCAT($C$3,"_",B5,"_",$C$2,"_",Parámetros!$C$6),DATA_KPI!$A:$H,6,FALSE),0) -> 11619684 | D5: =IFERROR(VLOOKUP(_xlfn.CONCAT($D$3,"_",B5,"_",$C$2,"_",Parámetros!$C$6),DATA_KPI!A:H,6,FALSE),0) -> 10407271 | E5: =IFERROR(+D5/C5,0) -> 0.89565869 | F5: =IFERROR(VLOOKUP(_xlfn.CONCAT($D$3,"_",B5,"_",$C$2,"_",Parámetros!$C$6),DATA_KPI_PRE!$A:$F,6,FALSE),0) -> 13351500 | G5: =IFERROR(+(D5/F5)-1,0) -> -0.22051673 | I5: =IFERROR(VLOOKUP(_xlfn.CONCAT($I$3,"_",B5,"_",$I$2,"_",Parámetros!$C$6),DATA_KPI!$A:$H,6,FALSE),0) -> 10210466 | J5: =IFERROR(VLOOKUP(_xlfn.CONCAT($J$3,"_",B5,"_",$I$2,"_",Parámetros!$C$6),DATA_KPI!$A:$H,6,FALSE),0) -> 9166486 | K5: =IFERROR(+J5/I5,0) -> 0.89775392 | L5: =IFERROR(VLOOKUP(_xlfn.CONCAT($J$3,"_",B5,"_",$I$2,"_",Parámetros!$C$6),DATA_KPI_PRE!A:F,6,FALSE),0) -> 11416506 | M5: =IFERROR(+(J5/L5)-1,0) -> -0.1970848 | O5: =IFERROR(VLOOKUP(_xlfn.CONCAT($O$3,"_",B5,"_",$O$2,"_",Parámetros!$C$6),DATA_KPI!$A:$H,6,FALSE),0) -> 1405686.7 | P5: =IFERROR(VLOOKUP(_xlfn.CONCAT($P$3,"_",B5,"_",$O$2,"_",Parámetros!$C$6),DATA_KPI!$A:$H,6,FALSE),0) -> 1222280.4 | Q5: =IFERROR(+P5/O5,0) -> 0.8695255 | R5: =IFERROR(VLOOKUP(_xlfn.CONCAT($P$3,"_",B5,"_",$O$2,"_",Parámetros!$C$6),DATA_KPI_PRE!A:F,6,FALSE),0) -> 1934994.3 | S5: =IFERROR(+(P5/R5)-1,0) -> -0.36832865 | U5: =IFERROR(VLOOKUP(_xlfn.CONCAT($U$3,"_",B5,"_",$U$2,"_",Parámetros!$C$6),DATA_KPI!$A:$H,6,FALSE),0) -> 0 | V5: =IFERROR(VLOOKUP(_xlfn.CONCAT($V$3,"_",B5,"_",$U$2,"_",Parámetros!$C$6),DATA_KPI!$A:$H,6,FALSE),0) -> 0 | W5: =IFERROR(+V5/U5,0) -> 0 | X5: =IFERROR(VLOOKUP(_xlfn.CONCAT($V$3,"_",B5,"_",$U$2,"_",Parámetros!$C$6),DATA_KPI_PRE!A:F,6,FALSE),0) -> 0 | Y5: =IFERROR(+(V5/X5)-1,0) -> 0 | AA5: =IFERROR(VLOOKUP(_xlfn.CONCAT($AA$3,"_",B5,"_",$AA$2,"_",Parámetros!$C$6),DATA_KPI!$A:$H,6,FALSE),0) -> 3530.98 | AB5: =IFERROR(VLOOKUP(_xlfn.CONCAT($AB$3,"_",B5,"_",$AA$2,"_",Parámetros!$C$6),DATA_KPI!$A:$H,6,FALSE),0) -> 18504.43 | AC5: =IFERROR(+AB5/AA5,0) -> 5.2405933 | AD5: =IFERROR(VLOOKUP(_xlfn.CONCAT($AB$3,"_",B5,"_",$AA$2,"_",Parámetros!$C$6),DATA_KPI_PRE!A:F,6,FALSE),0) -> 0 | AE5: =IFERROR(+(AB5/AD5)-1,0) -> 0 | AG5: =IFERROR(VLOOKUP(_xlfn.CONCAT($AG$3,"_",B5,"_",$AG$2,"_",Parámetros!$C$6),DATA_KPI!$A:$H,6,FALSE),0) -> 0 | AH5: =IFERROR(VLOOKUP(_xlfn.CONCAT($AH$3,"_",B5,"_",$AG$2,"_",Parámetros!$C$6),DATA_KPI!$A:$H,6,FALSE),0) -> 0 | AI5: =IFERROR(+AH5/AG5,0) -> 0 | AJ5: =IFERROR(VLOOKUP(_xlfn.CONCAT($AH$3,"_",B5,"_",$AG$2,"_",Parámetros!$C$6),DATA_KPI_PRE!A:F,6,FALSE),0) -> 0 | AK5: =IFERROR(+(AH5/AJ5)-1,0) -> 0 | AM5: =IFERROR(VLOOKUP(_xlfn.CONCAT($AM$3,"_",B5,"_",$AM$2,"_",Parámetros!$C$6),DATA_KPI!$A:$H,6,FALSE),0) -> 0 | AN5: =IFERROR(VLOOKUP(_xlfn.CONCAT($AN$3,"_",B5,"_",$AM$2,"_",Parámetros!$C$6),DATA_KPI!$A:$H,6,FALSE),0) -> 0 | AO5: =IFERROR(+AN5/AM5,0) -> 0 | AP5: =IFERROR(VLOOKUP(_xlfn.CONCAT($AN$3,"_",B5,"_",$AM$2,"_",Parámetros!$C$6),DATA_KPI_PRE!A:F,6,FALSE),0) -> 0 | AQ5: =IFERROR(+(AN5/AP5)-1,0) -> 0 | AS5: =IFERROR(J5/D5,0) -> 0.88077711 | AT5: =IFERROR(P5/D5,0) -> 0.11744486 | AU5: =IFERROR(V5/D5,0) -> 0 | AV5: =IFERROR(AB5/D5,0) -> 0.001778029 | AW5: =IFERROR(AH5/D5,0) -> 0 | AX5: =IFERROR(AN5/D5,0) -> 0 | AY5: =SUM(AS5:AX5) -> 1 | BA5: Part. V Ventanitas UBER | BB5: =AH53/AH57 -> 0.15110035
A6: Cartago | B6: =IF(IFERROR(VLOOKUP(A6,DATA_KPI!$D:$H,5,FALSE),"")="",VLOOKUP(A6,DATA_KPI_PRE!$D:$H,5,FALSE),VLOOKUP(A6,DATA_KPI!$D:$H,5,FALSE)) -> S42 | C6: =IFERROR(VLOOKUP(_xlfn.CONCAT($C$3,"_",B6,"_",$C$2,"_",Parámetros!$C$6),DATA_KPI!$A:$H,6,FALSE),0) -> 17205595 | D6: =IFERROR(VLOOKUP(_xlfn.CONCAT($D$3,"_",B6,"_",$C$2,"_",Parámetros!$C$6),DATA_KPI!A:H,6,FALSE),0) -> 16537087 | E6: =IFERROR(+(D6/C6)-1,0) -> -0.038854105 | F6: =IFERROR(VLOOKUP(_xlfn.CONCAT($D$3,"_",B6,"_",$C$2,"_",Parámetros!$C$6),DATA_KPI_PRE!$A:$F,6,FALSE),0) -> 17173291 | G6: =IFERROR(+(D6/F6)-1,0) -> -0.037046105 | I6: =IFERROR(VLOOKUP(_xlfn.CONCAT($I$3,"_",B6,"_",$I$2,"_",Parámetros!$C$6),DATA_KPI!$A:$H,6,FALSE),0) -> 9360675.3 | J6: =IFERROR(VLOOKUP(_xlfn.CONCAT($J$3,"_",B6,"_",$I$2,"_",Parámetros!$C$6),DATA_KPI!$A:$H,6,FALSE),0) -> 8251107.7 | K6: =IFERROR(+(J6/I6)-1,0) -> -0.11853499 | L6: =IFERROR(VLOOKUP(_xlfn.CONCAT($J$3,"_",B6,"_",$I$2,"_",Parámetros!$C$6),DATA_KPI_PRE!A:F,6,FALSE),0) -> 9165892.1 | M6: =IFERROR(+(J6/L6)-1,0) -> -0.099803092 | O6: =IFERROR(VLOOKUP(_xlfn.CONCAT($O$3,"_",B6,"_",$O$2,"_",Parámetros!$C$6),DATA_KPI!$A:$H,6,FALSE),0) -> 1127047 | P6: =IFERROR(VLOOKUP(_xlfn.CONCAT($P$3,"_",B6,"_",$O$2,"_",Parámetros!$C$6),DATA_KPI!$A:$H,6,FALSE),0) -> 628475.62 | Q6: =IFERROR(+(P6/O6)-1,0) -> -0.44236966 | R6: =IFERROR(VLOOKUP(_xlfn.CONCAT($P$3,"_",B6,"_",$O$2,"_",Parámetros!$C$6),DATA_KPI_PRE!A:F,6,FALSE),0) -> 1584457.3 | S6: =IFERROR(+(P6/R6)-1,0) -> -0.60334961 | U6: =IFERROR(VLOOKUP(_xlfn.CONCAT($U$3,"_",B6,"_",$U$2,"_",Parámetros!$C$6),DATA_KPI!$A:$H,6,FALSE),0) -> 0 | V6: =IFERROR(VLOOKUP(_xlfn.CONCAT($V$3,"_",B6,"_",$U$2,"_",Parámetros!$C$6),DATA_KPI!$A:$H,6,FALSE),0) -> 0 | W6: =IFERROR(+(V6/U6)-1,0) -> 0 | X6: =IFERROR(VLOOKUP(_xlfn.CONCAT($V$3,"_",B6,"_",$U$2,"_",Parámetros!$C$6),DATA_KPI_PRE!A:F,6,FALSE),0) -> 0 | Y6: =IFERROR(+(V6/X6)-1,0) -> 0 | AA6: =IFERROR(VLOOKUP(_xlfn.CONCAT($AA$3,"_",B6,"_",$AA$2,"_",Parámetros!$C$6),DATA_KPI!$A:$H,6,FALSE),0) -> 301657.6 | AB6: =IFERROR(VLOOKUP(_xlfn.CONCAT($AB$3,"_",B6,"_",$AA$2,"_",Parámetros!$C$6),DATA_KPI!$A:$H,6,FALSE),0) -> 397321.4 | AC6: =IFERROR(+(AB6/AA6)-1,0) -> 0.3171271 | AD6: =IFERROR(VLOOKUP(_xlfn.CONCAT($AB$3,"_",B6,"_",$AA$2,"_",Parámetros!$C$6),DATA_KPI_PRE!A:F,6,FALSE),0) -> 103594.97 | AE6: =IFERROR(+(AB6/AD6)-1,0) -> 2.8353348 | AG6: =IFERROR(VLOOKUP(_xlfn.CONCAT($AG$3,"_",B6,"_",$AG$2,"_",Parámetros!$C$6),DATA_KPI!$A:$H,6,FALSE),0) -> 6386731.9 | AH6: =IFERROR(VLOOKUP(_xlfn.CONCAT($AH$3,"_",B6,"_",$AG$2,"_",Parámetros!$C$6),DATA_KPI!$A:$H,6,FALSE),0) -> 7232788.8 | AI6: =IFERROR(+(AH6/AG6)-1,0) -> 0.13247102 | AJ6: =IFERROR(VLOOKUP(_xlfn.CONCAT($AH$3,"_",B6,"_",$AG$2,"_",Parámetros!$C$6),DATA_KPI_PRE!A:F,6,FALSE),0) -> 6268588.6 | AK6: =IFERROR(+(AH6/AJ6)-1,0) -> 0.15381455 | AM6: =IFERROR(VLOOKUP(_xlfn.CONCAT($AM$3,"_",B6,"_",$AM$2,"_",Parámetros!$C$6),DATA_KPI!$A:$H,6,FALSE),0) -> 29483.2 | AN6: =IFERROR(VLOOKUP(_xlfn.CONCAT($AN$3,"_",B6,"_",$AM$2,"_",Parámetros!$C$6),DATA_KPI!$A:$H,6,FALSE),0) -> 27393.47 | AO6: =IFERROR(+AN6/AM6,0) -> 0.92912133 | AP6: =IFERROR(VLOOKUP(_xlfn.CONCAT($AN$3,"_",B6,"_",$AM$2,"_",Parámetros!$C$6),DATA_KPI_PRE!A:F,6,FALSE),0) -> 50757.497 | AQ6: =IFERROR(+(AN6/AP6)-1,0) -> -0.46030691 | AS6: =J6/D6 -> 0.49894566 | AT6: =P6/D6 -> 0.03800401 | AU6: =V6/D6 -> 0 | AV6: =AB6/D6 -> 0.024026081 | AW6: =AH6/D6 -> 0.43736777 | AX6: =AN6/D6 -> 0.001656487 | AY6: =SUM(AS6:AX6) -> 1
A7: City Mall | B7: =IF(IFERROR(VLOOKUP(A7,DATA_KPI!$D:$H,5,FALSE),"")="",VLOOKUP(A7,DATA_KPI_PRE!$D:$H,5,FALSE),VLOOKUP(A7,DATA_KPI!$D:$H,5,FALSE)) -> S38 | C7: =IFERROR(VLOOKUP(_xlfn.CONCAT($C$3,"_",B7,"_",$C$2,"_",Parámetros!$C$6),DATA_KPI!$A:$H,6,FALSE),0) -> 16382347 | D7: =IFERROR(VLOOKUP(_xlfn.CONCAT($D$3,"_",B7,"_",$C$2,"_",Parámetros!$C$6),DATA_KPI!A:H,6,FALSE),0) -> 13768826 | E7: =IFERROR(+(D7/C7)-1,0) -> -0.1595328 | F7: =IFERROR(VLOOKUP(_xlfn.CONCAT($D$3,"_",B7,"_",$C$2,"_",Parámetros!$C$6),DATA_KPI_PRE!$A:$F,6,FALSE),0) -> 15466880 | G7: =IFERROR(+(D7/F7)-1,0) -> -0.10978646 | I7: =IFERROR(VLOOKUP(_xlfn.CONCAT($I$3,"_",B7,"_",$I$2,"_",Parámetros!$C$6),DATA_KPI!$A:$H,6,FALSE),0) -> 15581772 | J7: =IFERROR(VLOOKUP(_xlfn.CONCAT($J$3,"_",B7,"_",$I$2,"_",Parámetros!$C$6),DATA_KPI!$A:$H,6,FALSE),0) -> 13647491 | K7: =IFERROR(+(J7/I7)-1,0) -> -0.12413744 | L7: =IFERROR(VLOOKUP(_xlfn.CONCAT($J$3,"_",B7,"_",$I$2,"_",Parámetros!$C$6),DATA_KPI_PRE!A:F,6,FALSE),0) -> 15120405 | M7: =IFERROR(+(J7/L7)-1,0) -> -0.097412363 | O7: =IFERROR(VLOOKUP(_xlfn.CONCAT($O$3,"_",B7,"_",$O$2,"_",Parámetros!$C$6),DATA_KPI!$A:$H,6,FALSE),0) -> 210914.9 | P7: =IFERROR(VLOOKUP(_xlfn.CONCAT($P$3,"_",B7,"_",$O$2,"_",Parámetros!$C$6),DATA_KPI!$A:$H,6,FALSE),0) -> 121335.1 | Q7: =IFERROR(+(P7/O7)-1,0) -> -0.42472011 | R7: =IFERROR(VLOOKUP(_xlfn.CONCAT($P$3,"_",B7,"_",$O$2,"_",Parámetros!$C$6),DATA_KPI_PRE!A:F,6,FALSE),0) -> 346474.62 | S7: =IFERROR(+(P7/R7)-1,0) -> -0.6498009 | U7: =IFERROR(VLOOKUP(_xlfn.CONCAT($U$3,"_",B7,"_",$U$2,"_",Parámetros!$C$6),DATA_KPI!$A:$H,6,FALSE),0) -> 0 | V7: =IFERROR(VLOOKUP(_xlfn.CONCAT($V$3,"_",B7,"_",$U$2,"_",Parámetros!$C$6),DATA_KPI!$A:$H,6,FALSE),0) -> 0 | W7: =IFERROR(+(V7/U7)-1,0) -> 0 | X7: =IFERROR(VLOOKUP(_xlfn.CONCAT($V$3,"_",B7,"_",$U$2,"_",Parámetros!$C$6),DATA_KPI_PRE!A:F,6,FALSE),0) -> 0 | Y7: =IFERROR(+(V7/X7)-1,0) -> 0 | AA7: =IFERROR(VLOOKUP(_xlfn.CONCAT($AA$3,"_",B7,"_",$AA$2,"_",Parámetros!$C$6),DATA_KPI!$A:$H,6,FALSE),0) -> 0 | AB7: =IFERROR(VLOOKUP(_xlfn.CONCAT($AB$3,"_",B7,"_",$AA$2,"_",Parámetros!$C$6),DATA_KPI!$A:$H,6,FALSE),0) -> 0 | AC7: =IFERROR(+(AB7/AA7)-1,0) -> 0 | AD7: =IFERROR(VLOOKUP(_xlfn.CONCAT($AB$3,"_",B7,"_",$AA$2,"_",Parámetros!$C$6),DATA_KPI_PRE!A:F,6,FALSE),0) -> 0 | AE7: =IFERROR(+(AB7/AD7)-1,0) -> 0 | AG7: =IFERROR(VLOOKUP(_xlfn.CONCAT($AG$3,"_",B7,"_",$AG$2,"_",Parámetros!$C$6),DATA_KPI!$A:$H,6,FALSE),0) -> 589660.6 | AH7: =IFERROR(VLOOKUP(_xlfn.CONCAT($AH$3,"_",B7,"_",$AG$2,"_",Parámetros!$C$6),DATA_KPI!$A:$H,6,FALSE),0) -> 0 | AI7: =IFERROR(+(AH7/AG7)-1,0) -> -1 | AJ7: =IFERROR(VLOOKUP(_xlfn.CONCAT($AH$3,"_",B7,"_",$AG$2,"_",Parámetros!$C$6),DATA_KPI_PRE!A:F,6,FALSE),0) -> 0 | AK7: =IFERROR(+(AH7/AJ7)-1,0) -> 0 | AM7: =IFERROR(VLOOKUP(_xlfn.CONCAT($AM$3,"_",B7,"_",$AM$2,"_",Parámetros!$C$6),DATA_KPI!$A:$H,6,FALSE),0) -> 0 | AN7: =IFERROR(VLOOKUP(_xlfn.CONCAT($AN$3,"_",B7,"_",$AM$2,"_",Parámetros!$C$6),DATA_KPI!$A:$H,6,FALSE),0) -> 0 | AO7: =IFERROR(+AN7/AM7,0) -> 0 | AP7: =IFERROR(VLOOKUP(_xlfn.CONCAT($AN$3,"_",B7,"_",$AM$2,"_",Parámetros!$C$6),DATA_KPI_PRE!A:F,6,FALSE),0) -> 0 | AQ7: =IFERROR(+(AN7/AP7)-1,0) -> 0 | AS7: =J7/D7 -> 0.99118769 | AT7: =P7/D7 -> 0.0088123056 | AU7: =V7/D7 -> 0 | AV7: =AB7/D7 -> 0 | AW7: =AH7/D7 -> 0 | AX7: =AN7/D7 -> 0 | AY7: =SUM(AS7:AX7) -> 1
A8: Coronado | B8: =IF(IFERROR(VLOOKUP(A8,DATA_KPI!$D:$H,5,FALSE),"")="",VLOOKUP(A8,DATA_KPI_PRE!$D:$H,5,FALSE),VLOOKUP(A8,DATA_KPI!$D:$H,5,FALSE)) -> S71 | C8: =IFERROR(VLOOKUP(_xlfn.CONCAT($C$3,"_",B8,"_",$C$2,"_",Parámetros!$C$6),DATA_KPI!$A:$H,6,FALSE),0) -> 16267031 | D8: =IFERROR(VLOOKUP(_xlfn.CONCAT($D$3,"_",B8,"_",$C$2,"_",Parámetros!$C$6),DATA_KPI!A:H,6,FALSE),0) -> 15370828 | E8: =IFERROR(+(D8/C8)-1,0) -> -0.055093207 | F8: =IFERROR(VLOOKUP(_xlfn.CONCAT($D$3,"_",B8,"_",$C$2,"_",Parámetros!$C$6),DATA_KPI_PRE!$A:$F,6,FALSE),0) -> 15966897 | G8: =IFERROR(+(D8/F8)-1,0) -> -0.037331549 | I8: =IFERROR(VLOOKUP(_xlfn.CONCAT($I$3,"_",B8,"_",$I$2,"_",Parámetros!$C$6),DATA_KPI!$A:$H,6,FALSE),0) -> 6372211.1 | J8: =IFERROR(VLOOKUP(_xlfn.CONCAT($J$3,"_",B8,"_",$I$2,"_",Parámetros!$C$6),DATA_KPI!$A:$H,6,FALSE),0) -> 6920079 | K8: =IFERROR(+(J8/I8)-1,0) -> 0.085977679 | L8: =IFERROR(VLOOKUP(_xlfn.CONCAT($J$3,"_",B8,"_",$I$2,"_",Parámetros!$C$6),DATA_KPI_PRE!A:F,6,FALSE),0) -> 5809254.5 | M8: =IFERROR(+(J8/L8)-1,0) -> 0.19121636 | O8: =IFERROR(VLOOKUP(_xlfn.CONCAT($O$3,"_",B8,"_",$O$2,"_",Parámetros!$C$6),DATA_KPI!$A:$H,6,FALSE),0) -> 2090064 | P8: =IFERROR(VLOOKUP(_xlfn.CONCAT($P$3,"_",B8,"_",$O$2,"_",Parámetros!$C$6),DATA_KPI!$A:$H,6,FALSE),0) -> 1176104.4 | Q8: =IFERROR(+(P8/O8)-1,0) -> -0.43728787 | R8: =IFERROR(VLOOKUP(_xlfn.CONCAT($P$3,"_",B8,"_",$O$2,"_",Parámetros!$C$6),DATA_KPI_PRE!A:F,6,FALSE),0) -> 2146748.5 | S8: =IFERROR(+(P8/R8)-1,0) -> -0.45214618 | U8: =IFERROR(VLOOKUP(_xlfn.CONCAT($U$3,"_",B8,"_",$U$2,"_",Parámetros!$C$6),DATA_KPI!$A:$H,6,FALSE),0) -> 0 | V8: =IFERROR(VLOOKUP(_xlfn.CONCAT($V$3,"_",B8,"_",$U$2,"_",Parámetros!$C$6),DATA_KPI!$A:$H,6,FALSE),0) -> 0 | W8: =IFERROR(+(V8/U8)-1,0) -> 0 | X8: =IFERROR(VLOOKUP(_xlfn.CONCAT($V$3,"_",B8,"_",$U$2,"_",Parámetros!$C$6),DATA_KPI_PRE!A:F,6,FALSE),0) -> 0 | Y8: =IFERROR(+(V8/X8)-1,0) -> 0 | AA8: =IFERROR(VLOOKUP(_xlfn.CONCAT($AA$3,"_",B8,"_",$AA$2,"_",Parámetros!$C$6),DATA_KPI!$A:$H,6,FALSE),0) -> 275743.47 | AB8: =IFERROR(VLOOKUP(_xlfn.CONCAT($AB$3,"_",B8,"_",$AA$2,"_",Parámetros!$C$6),DATA_KPI!$A:$H,6,FALSE),0) -> 80646.02 | AC8: =IFERROR(+(AB8/AA8)-1,0) -> -0.70753244 | AD8: =IFERROR(VLOOKUP(_xlfn.CONCAT($AB$3,"_",B8,"_",$AA$2,"_",Parámetros!$C$6),DATA_KPI_PRE!A:F,6,FALSE),0) -> 868656.18 | AE8: =IFERROR(+(AB8/AD8)-1,0) -> -0.90716002 | AG8: =IFERROR(VLOOKUP(_xlfn.CONCAT($AG$3,"_",B8,"_",$AG$2,"_",Parámetros!$C$6),DATA_KPI!$A:$H,6,FALSE),0) -> 7529012.1 | AH8: =IFERROR(VLOOKUP(_xlfn.CONCAT($AH$3,"_",B8,"_",$AG$2,"_",Parámetros!$C$6),DATA_KPI!$A:$H,6,FALSE),0) -> 6993822.8 | AI8: =IFERROR(+(AH8/AG8)-1,0) -> -0.071083611 | AJ8: =IFERROR(VLOOKUP(_xlfn.CONCAT($AH$3,"_",B8,"_",$AG$2,"_",Parámetros!$C$6),DATA_KPI_PRE!A:F,6,FALSE),0) -> 7138051.6 | AK8: =IFERROR(+(AH8/AJ8)-1,0) -> -0.020205631 | AM8: =IFERROR(VLOOKUP(_xlfn.CONCAT($AM$3,"_",B8,"_",$AM$2,"_",Parámetros!$C$6),DATA_KPI!$A:$H,6,FALSE),0) -> 0 | AN8: =IFERROR(VLOOKUP(_xlfn.CONCAT($AN$3,"_",B8,"_",$AM$2,"_",Parámetros!$C$6),DATA_KPI!$A:$H,6,FALSE),0) -> 200175.67 | AO8: =IFERROR(+AN8/AM8,0) -> 0 | AP8: =IFERROR(VLOOKUP(_xlfn.CONCAT($AN$3,"_",B8,"_",$AM$2,"_",Parámetros!$C$6),DATA_KPI_PRE!A:F,6,FALSE),0) -> 4186.0315 | AQ8: =IFERROR(+(AN8/AP8)-1,0) -> 46.819914 | AS8: =J8/D8 -> 0.45020861 | AT8: =P8/D8 -> 0.076515357 | AU8: =V8/D8 -> 0 | AV8: =AB8/D8 -> 0.0052466933 | AW8: =AH8/D8 -> 0.45500625 | AX8: =AN8/D8 -> 0.01302309 | AY8: =SUM(AS8:AX8) -> 1
A9: Curridabat | B9: =IF(IFERROR(VLOOKUP(A9,DATA_KPI!$D:$H,5,FALSE),"")="",VLOOKUP(A9,DATA_KPI_PRE!$D:$H,5,FALSE),VLOOKUP(A9,DATA_KPI!$D:$H,5,FALSE)) -> S12 | C9: =IFERROR(VLOOKUP(_xlfn.CONCAT($C$3,"_",B9,"_",$C$2,"_",Parámetros!$C$6),DATA_KPI!$A:$H,6,FALSE),0) -> 24447375 | D9: =IFERROR(VLOOKUP(_xlfn.CONCAT($D$3,"_",B9,"_",$C$2,"_",Parámetros!$C$6),DATA_KPI!A:H,6,FALSE),0) -> 21786623 | E9: =IFERROR(+(D9/C9)-1,0) -> -0.10883589 | F9: =IFERROR(VLOOKUP(_xlfn.CONCAT($D$3,"_",B9,"_",$C$2,"_",Parámetros!$C$6),DATA_KPI_PRE!$A:$F,6,FALSE),0) -> 22970475 | G9: =IFERROR(+(D9/F9)-1,0) -> -0.051537988 | I9: =IFERROR(VLOOKUP(_xlfn.CONCAT($I$3,"_",B9,"_",$I$2,"_",Parámetros!$C$6),DATA_KPI!$A:$H,6,FALSE),0) -> 14872712 | J9: =IFERROR(VLOOKUP(_xlfn.CONCAT($J$3,"_",B9,"_",$I$2,"_",Parámetros!$C$6),DATA_KPI!$A:$H,6,FALSE),0) -> 13225496 | K9: =IFERROR(+(J9/I9)-1,0) -> -0.11075424 | L9: =IFERROR(VLOOKUP(_xlfn.CONCAT($J$3,"_",B9,"_",$I$2,"_",Parámetros!$C$6),DATA_KPI_PRE!A:F,6,FALSE),0) -> 13579794 | M9: =IFERROR(+(J9/L9)-1,0) -> -0.026090098 | O9: =IFERROR(VLOOKUP(_xlfn.CONCAT($O$3,"_",B9,"_",$O$2,"_",Parámetros!$C$6),DATA_KPI!$A:$H,6,FALSE),0) -> 2205356.6 | P9: =IFERROR(VLOOKUP(_xlfn.CONCAT($P$3,"_",B9,"_",$O$2,"_",Parámetros!$C$6),DATA_KPI!$A:$H,6,FALSE),0) -> 1727867.5 | Q9: =IFERROR(+(P9/O9)-1,0) -> -0.21651334 | R9: =IFERROR(VLOOKUP(_xlfn.CONCAT($P$3,"_",B9,"_",$O$2,"_",Parámetros!$C$6),DATA_KPI_PRE!A:F,6,FALSE),0) -> 2152914.8 | S9: =IFERROR(+(P9/R9)-1,0) -> -0.19742878 | U9: =IFERROR(VLOOKUP(_xlfn.CONCAT($U$3,"_",B9,"_",$U$2,"_",Parámetros!$C$6),DATA_KPI!$A:$H,6,FALSE),0) -> 0 | V9: =IFERROR(VLOOKUP(_xlfn.CONCAT($V$3,"_",B9,"_",$U$2,"_",Parámetros!$C$6),DATA_KPI!$A:$H,6,FALSE),0) -> 0 | W9: =IFERROR(+(V9/U9)-1,0) -> 0 | X9: =IFERROR(VLOOKUP(_xlfn.CONCAT($V$3,"_",B9,"_",$U$2,"_",Parámetros!$C$6),DATA_KPI_PRE!A:F,6,FALSE),0) -> 0 | Y9: =IFERROR(+(V9/X9)-1,0) -> 0 | AA9: =IFERROR(VLOOKUP(_xlfn.CONCAT($AA$3,"_",B9,"_",$AA$2,"_",Parámetros!$C$6),DATA_KPI!$A:$H,6,FALSE),0) -> 1017596 | AB9: =IFERROR(VLOOKUP(_xlfn.CONCAT($AB$3,"_",B9,"_",$AA$2,"_",Parámetros!$C$6),DATA_KPI!$A:$H,6,FALSE),0) -> 646981.68 | AC9: =IFERROR(+(AB9/AA9)-1,0) -> -0.36420576 | AD9: =IFERROR(VLOOKUP(_xlfn.CONCAT($AB$3,"_",B9,"_",$AA$2,"_",Parámetros!$C$6),DATA_KPI_PRE!A:F,6,FALSE),0) -> 1247389.5 | AE9: =IFERROR(+(AB9/AD9)-1,0) -> -0.48133149 | AG9: =IFERROR(VLOOKUP(_xlfn.CONCAT($AG$3,"_",B9,"_",$AG$2,"_",Parámetros!$C$6),DATA_KPI!$A:$H,6,FALSE),0) -> 6320125.9 | AH9: =IFERROR(VLOOKUP(_xlfn.CONCAT($AH$3,"_",B9,"_",$AG$2,"_",Parámetros!$C$6),DATA_KPI!$A:$H,6,FALSE),0) -> 6048879.1 | AI9: =IFERROR(+(AH9/AG9)-1,0) -> -0.042917942 | AJ9: =IFERROR(VLOOKUP(_xlfn.CONCAT($AH$3,"_",B9,"_",$AG$2,"_",Parámetros!$C$6),DATA_KPI_PRE!A:F,6,FALSE),0) -> 5933870.2 | AK9: =IFERROR(+(AH9/AJ9)-1,0) -> 0.019381782 | AM9: =IFERROR(VLOOKUP(_xlfn.CONCAT($AM$3,"_",B9,"_",$AM$2,"_",Parámetros!$C$6),DATA_KPI!$A:$H,6,FALSE),0) -> 31584.07 | AN9: =IFERROR(VLOOKUP(_xlfn.CONCAT($AN$3,"_",B9,"_",$AM$2,"_",Parámetros!$C$6),DATA_KPI!$A:$H,6,FALSE),0) -> 137398.32 | AO9: =IFERROR(+AN9/AM9,0) -> 4.3502411 | AP9: =IFERROR(VLOOKUP(_xlfn.CONCAT($AN$3,"_",B9,"_",$AM$2,"_",Parámetros!$C$6),DATA_KPI_PRE!A:F,6,FALSE),0) -> 56505.964 | AQ9: =IFERROR(+(AN9/AP9)-1,0) -> 1.431572 | AS9: =J9/D9 -> 0.60704664 | AT9: =P9/D9 -> 0.079308643 | AU9: =V9/D9 -> 0 | AV9: =AB9/D9 -> 0.029696281 | AW9: =AH9/D9 -> 0.27764189 | AX9: =AN9/D9 -> 0.0063065451 | AY9: =SUM(AS9:AX9) -> 1
A10: Desamparados | B10: =IF(IFERROR(VLOOKUP(A10,DATA_KPI!$D:$H,5,FALSE),"")="",VLOOKUP(A10,DATA_KPI_PRE!$D:$H,5,FALSE),VLOOKUP(A10,DATA_KPI!$D:$H,5,FALSE)) -> S04 | C10: =IFERROR(VLOOKUP(_xlfn.CONCAT($C$3,"_",B10,"_",$C$2,"_",Parámetros!$C$6),DATA_KPI!$A:$H,6,FALSE),0) -> 21489239 | D10: =IFERROR(VLOOKUP(_xlfn.CONCAT($D$3,"_",B10,"_",$C$2,"_",Parámetros!$C$6),DATA_KPI!A:H,6,FALSE),0) -> 19396479 | E10: =IFERROR(+(D10/C10)-1,0) -> -0.097386435 | F10: =IFERROR(VLOOKUP(_xlfn.CONCAT($D$3,"_",B10,"_",$C$2,"_",Parámetros!$C$6),DATA_KPI_PRE!$A:$F,6,FALSE),0) -> 21440108 | G10: =IFERROR(+(D10/F10)-1,0) -> -0.095318062 | I10: =IFERROR(VLOOKUP(_xlfn.CONCAT($I$3,"_",B10,"_",$I$2,"_",Parámetros!$C$6),DATA_KPI!$A:$H,6,FALSE),0) -> 9393659.5 | J10: =IFERROR(VLOOKUP(_xlfn.CONCAT($J$3,"_",B10,"_",$I$2,"_",Parámetros!$C$6),DATA_KPI!$A:$H,6,FALSE),0) -> 9927208.6 | K10: =IFERROR(+(J10/I10)-1,0) -> 0.056798854 | L10: =IFERROR(VLOOKUP(_xlfn.CONCAT($J$3,"_",B10,"_",$I$2,"_",Parámetros!$C$6),DATA_KPI_PRE!A:F,6,FALSE),0) -> 8858545.5 | M10: =IFERROR(+(J10/L10)-1,0) -> 0.12063641 | O10: =IFERROR(VLOOKUP(_xlfn.CONCAT($O$3,"_",B10,"_",$O$2,"_",Parámetros!$C$6),DATA_KPI!$A:$H,6,FALSE),0) -> 2394926.5 | P10: =IFERROR(VLOOKUP(_xlfn.CONCAT($P$3,"_",B10,"_",$O$2,"_",Parámetros!$C$6),DATA_KPI!$A:$H,6,FALSE),0) -> 1199912.4 | Q10: =IFERROR(+(P10/O10)-1,0) -> -0.49897738 | R10: =IFERROR(VLOOKUP(_xlfn.CONCAT($P$3,"_",B10,"_",$O$2,"_",Parámetros!$C$6),DATA_KPI_PRE!A:F,6,FALSE),0) -> 2338615.8 | S10: =IFERROR(+(P10/R10)-1,0) -> -0.48691342 | U10: =IFERROR(VLOOKUP(_xlfn.CONCAT($U$3,"_",B10,"_",$U$2,"_",Parámetros!$C$6),DATA_KPI!$A:$H,6,FALSE),0) -> 0 | V10: =IFERROR(VLOOKUP(_xlfn.CONCAT($V$3,"_",B10,"_",$U$2,"_",Parámetros!$C$6),DATA_KPI!$A:$H,6,FALSE),0) -> 0 | W10: =IFERROR(+(V10/U10)-1,0) -> 0 | X10: =IFERROR(VLOOKUP(_xlfn.CONCAT($V$3,"_",B10,"_",$U$2,"_",Parámetros!$C$6),DATA_KPI_PRE!A:F,6,FALSE),0) -> 0 | Y10: =IFERROR(+(V10/X10)-1,0) -> 0 | AA10: =IFERROR(VLOOKUP(_xlfn.CONCAT($AA$3,"_",B10,"_",$AA$2,"_",Parámetros!$C$6),DATA_KPI!$A:$H,6,FALSE),0) -> 765351.67 | AB10: =IFERROR(VLOOKUP(_xlfn.CONCAT($AB$3,"_",B10,"_",$AA$2,"_",Parámetros!$C$6),DATA_KPI!$A:$H,6,FALSE),0) -> 459366.47 | AC10: =IFERROR(+(AB10/AA10)-1,0) -> -0.39979687 | AD10: =IFERROR(VLOOKUP(_xlfn.CONCAT($AB$3,"_",B10,"_",$AA$2,"_",Parámetros!$C$6),DATA_KPI_PRE!A:F,6,FALSE),0) -> 1034549.5 | AE10: =IFERROR(+(AB10/AD10)-1,0) -> -0.55597441 | AG10: =IFERROR(VLOOKUP(_xlfn.CONCAT($AG$3,"_",B10,"_",$AG$2,"_",Parámetros!$C$6),DATA_KPI!$A:$H,6,FALSE),0) -> 8841522.8 | AH10: =IFERROR(VLOOKUP(_xlfn.CONCAT($AH$3,"_",B10,"_",$AG$2,"_",Parámetros!$C$6),DATA_KPI!$A:$H,6,FALSE),0) -> 7673751.6 | AI10: =IFERROR(+(AH10/AG10)-1,0) -> -0.13207806 | AJ10: =IFERROR(VLOOKUP(_xlfn.CONCAT($AH$3,"_",B10,"_",$AG$2,"_",Parámetros!$C$6),DATA_KPI_PRE!A:F,6,FALSE),0) -> 9074387.4 | AK10: =IFERROR(+(AH10/AJ10)-1,0) -> -0.15435045 | AM10: =IFERROR(VLOOKUP(_xlfn.CONCAT($AM$3,"_",B10,"_",$AM$2,"_",Parámetros!$C$6),DATA_KPI!$A:$H,6,FALSE),0) -> 93778.75 | AN10: =IFERROR(VLOOKUP(_xlfn.CONCAT($AN$3,"_",B10,"_",$AM$2,"_",Parámetros!$C$6),DATA_KPI!$A:$H,6,FALSE),0) -> 136239.82 | AO10: =IFERROR(+AN10/AM10,0) -> 1.4527792 | AP10: =IFERROR(VLOOKUP(_xlfn.CONCAT($AN$3,"_",B10,"_",$AM$2,"_",Parámetros!$C$6),DATA_KPI_PRE!A:F,6,FALSE),0) -> 134010.3 | AQ10: =IFERROR(+(AN10/AP10)-1,0) -> 0.016636938 | AS10: =J10/D10 -> 0.51180468 | AT10: =P10/D10 -> 0.061862382 | AU10: =V10/D10 -> 0 | AV10: =AB10/D10 -> 0.023682982 | AW10: =AH10/D10 -> 0.39562601 | AX10: =AN10/D10 -> 0.007023946 | AY10: =SUM(AS10:AX10) -> 1
A11: Escazú | B11: =IF(IFERROR(VLOOKUP(A11,DATA_KPI!$D:$H,5,FALSE),"")="",VLOOKUP(A11,DATA_KPI_PRE!$D:$H,5,FALSE),VLOOKUP(A11,DATA_KPI!$D:$H,5,FALSE)) -> S09 | C11: =IFERROR(VLOOKUP(_xlfn.CONCAT($C$3,"_",B11,"_",$C$2,"_",Parámetros!$C$6),DATA_KPI!$A:$H,6,FALSE),0) -> 20528584 | D11: =IFERROR(VLOOKUP(_xlfn.CONCAT($D$3,"_",B11,"_",$C$2,"_",Parámetros!$C$6),DATA_KPI!A:H,6,FALSE),0) -> 18410078 | E11: =IFERROR(+(D11/C11)-1,0) -> -0.10319786 | F11: =IFERROR(VLOOKUP(_xlfn.CONCAT($D$3,"_",B11,"_",$C$2,"_",Parámetros!$C$6),DATA_KPI_PRE!$A:$F,6,FALSE),0) -> 20662415 | G11: =IFERROR(+(D11/F11)-1,0) -> -0.10900647 | I11: =IFERROR(VLOOKUP(_xlfn.CONCAT($I$3,"_",B11,"_",$I$2,"_",Parámetros!$C$6),DATA_KPI!$A:$H,6,FALSE),0) -> 12079309 | J11: =IFERROR(VLOOKUP(_xlfn.CONCAT($J$3,"_",B11,"_",$I$2,"_",Parámetros!$C$6),DATA_KPI!$A:$H,6,FALSE),0) -> 9158915.5 | K11: =IFERROR(+(J11/I11)-1,0) -> -0.24176826 | L11: =IFERROR(VLOOKUP(_xlfn.CONCAT($J$3,"_",B11,"_",$I$2,"_",Parámetros!$C$6),DATA_KPI_PRE!A:F,6,FALSE),0) -> 10984028 | M11: =IFERROR(+(J11/L11)-1,0) -> -0.16616062 | O11: =IFERROR(VLOOKUP(_xlfn.CONCAT($O$3,"_",B11,"_",$O$2,"_",Parámetros!$C$6),DATA_KPI!$A:$H,6,FALSE),0) -> 1211329.3 | P11: =IFERROR(VLOOKUP(_xlfn.CONCAT($P$3,"_",B11,"_",$O$2,"_",Parámetros!$C$6),DATA_KPI!$A:$H,6,FALSE),0) -> 2077609.4 | Q11: =IFERROR(+(P11/O11)-1,0) -> 0.71514829 | R11: =IFERROR(VLOOKUP(_xlfn.CONCAT($P$3,"_",B11,"_",$O$2,"_",Parámetros!$C$6),DATA_KPI_PRE!A:F,6,FALSE),0) -> 1909851.2 | S11: =IFERROR(+(P11/R11)-1,0) -> 0.08783839 | U11: =IFERROR(VLOOKUP(_xlfn.CONCAT($U$3,"_",B11,"_",$U$2,"_",Parámetros!$C$6),DATA_KPI!$A:$H,6,FALSE),0) -> 0 | V11: =IFERROR(VLOOKUP(_xlfn.CONCAT($V$3,"_",B11,"_",$U$2,"_",Parámetros!$C$6),DATA_KPI!$A:$H,6,FALSE),0) -> 0 | W11: =IFERROR(+(V11/U11)-1,0) -> 0 | X11: =IFERROR(VLOOKUP(_xlfn.CONCAT($V$3,"_",B11,"_",$U$2,"_",Parámetros!$C$6),DATA_KPI_PRE!A:F,6,FALSE),0) -> 0 | Y11: =IFERROR(+(V11/X11)-1,0) -> 0 | AA11: =IFERROR(VLOOKUP(_xlfn.CONCAT($AA$3,"_",B11,"_",$AA$2,"_",Parámetros!$C$6),DATA_KPI!$A:$H,6,FALSE),0) -> 391701.02 | AB11: =IFERROR(VLOOKUP(_xlfn.CONCAT($AB$3,"_",B11,"_",$AA$2,"_",Parámetros!$C$6),DATA_KPI!$A:$H,6,FALSE),0) -> 410642.59 | AC11: =IFERROR(+(AB11/AA11)-1,0) -> 0.048357214 | AD11: =IFERROR(VLOOKUP(_xlfn.CONCAT($AB$3,"_",B11,"_",$AA$2,"_",Parámetros!$C$6),DATA_KPI_PRE!A:F,6,FALSE),0) -> 762686.99 | AE11: =IFERROR(+(AB11/AD11)-1,0) -> -0.46158438 | AG11: =IFERROR(VLOOKUP(_xlfn.CONCAT($AG$3,"_",B11,"_",$AG$2,"_",Parámetros!$C$6),DATA_KPI!$A:$H,6,FALSE),0) -> 6745334.1 | AH11: =IFERROR(VLOOKUP(_xlfn.CONCAT($AH$3,"_",B11,"_",$AG$2,"_",Parámetros!$C$6),DATA_KPI!$A:$H,6,FALSE),0) -> 6700753.5 | AI11: =IFERROR(+(AH11/AG11)-1,0) -> -0.0066090945 | AJ11: =IFERROR(VLOOKUP(_xlfn.CONCAT($AH$3,"_",B11,"_",$AG$2,"_",Parámetros!$C$6),DATA_KPI_PRE!A:F,6,FALSE),0) -> 6931984.5 | AK11: =IFERROR(+(AH11/AJ11)-1,0) -> -0.033357115 | AM11: =IFERROR(VLOOKUP(_xlfn.CONCAT($AM$3,"_",B11,"_",$AM$2,"_",Parámetros!$C$6),DATA_KPI!$A:$H,6,FALSE),0) -> 100910.14 | AN11: =IFERROR(VLOOKUP(_xlfn.CONCAT($AN$3,"_",B11,"_",$AM$2,"_",Parámetros!$C$6),DATA_KPI!$A:$H,6,FALSE),0) -> 62156.64 | AO11: =IFERROR(+AN11/AM11,0) -> 0.6159603 | AP11: =IFERROR(VLOOKUP(_xlfn.CONCAT($AN$3,"_",B11,"_",$AM$2,"_",Parámetros!$C$6),DATA_KPI_PRE!A:F,6,FALSE),0) -> 73863.423 | AQ11: =IFERROR(+(AN11/AP11)-1,0) -> -0.15849229 | AS11: =J11/D11 -> 0.49749467 | AT11: =P11/D11 -> 0.11285175 | AU11: =V11/D11 -> 0 | AV11: =AB11/D11 -> 0.022305315 | AW11: =AH11/D11 -> 0.36397204 | AX11: =AN11/D11 -> 0.0033762291 | AY11: =SUM(AS11:AX11) -> 1
A12: FC Parque Diversiones | B12: =IF(IFERROR(VLOOKUP(A12,DATA_KPI!$D:$H,5,FALSE),"")="",VLOOKUP(A12,DATA_KPI_PRE!$D:$H,5,FALSE),VLOOKUP(A12,DATA_KPI!$D:$H,5,FALSE)) -> S87 | C12: =IFERROR(VLOOKUP(_xlfn.CONCAT($C$3,"_",B12,"_",$C$2,"_",Parámetros!$C$6),DATA_KPI!$A:$H,6,FALSE),0) -> 21367546 | D12: =IFERROR(VLOOKUP(_xlfn.CONCAT($D$3,"_",B12,"_",$C$2,"_",Parámetros!$C$6),DATA_KPI!A:H,6,FALSE),0) -> 16296823 | E12: =IFERROR(+(D12/C12)-1,0) -> -0.23730956 | F12: =IFERROR(VLOOKUP(_xlfn.CONCAT($D$3,"_",B12,"_",$C$2,"_",Parámetros!$C$6),DATA_KPI_PRE!$A:$F,6,FALSE),0) -> 22571538 | G12: =IFERROR(+(D12/F12)-1,0) -> -0.27799235 | I12: =IFERROR(VLOOKUP(_xlfn.CONCAT($I$3,"_",B12,"_",$I$2,"_",Parámetros!$C$6),DATA_KPI!$A:$H,6,FALSE),0) -> 0 | J12: =IFERROR(VLOOKUP(_xlfn.CONCAT($J$3,"_",B12,"_",$I$2,"_",Parámetros!$C$6),DATA_KPI!$A:$H,6,FALSE),0) -> 1000602.9 | K12: =IFERROR(+(J12/I12)-1,0) -> 0 | L12: =IFERROR(VLOOKUP(_xlfn.CONCAT($J$3,"_",B12,"_",$I$2,"_",Parámetros!$C$6),DATA_KPI_PRE!A:F,6,FALSE),0) -> 0 | M12: =IFERROR(+(J12/L12)-1,0) -> 0 | O12: =IFERROR(VLOOKUP(_xlfn.CONCAT($O$3,"_",B12,"_",$O$2,"_",Parámetros!$C$6),DATA_KPI!$A:$H,6,FALSE),0) -> 21367546 | P12: =IFERROR(VLOOKUP(_xlfn.CONCAT($P$3,"_",B12,"_",$O$2,"_",Parámetros!$C$6),DATA_KPI!$A:$H,6,FALSE),0) -> 15296220 | Q12: =IFERROR(+(P12/O12)-1,0) -> -0.28413773 | R12: =IFERROR(VLOOKUP(_xlfn.CONCAT($P$3,"_",B12,"_",$O$2,"_",Parámetros!$C$6),DATA_KPI_PRE!A:F,6,FALSE),0) -> 22571538 | S12: =IFERROR(+(P12/R12)-1,0) -> -0.32232264 | U12: =IFERROR(VLOOKUP(_xlfn.CONCAT($U$3,"_",B12,"_",$U$2,"_",Parámetros!$C$6),DATA_KPI!$A:$H,6,FALSE),0) -> 0 | V12: =IFERROR(VLOOKUP(_xlfn.CONCAT($V$3,"_",B12,"_",$U$2,"_",Parámetros!$C$6),DATA_KPI!$A:$H,6,FALSE),0) -> 0 | W12: =IFERROR(+(V12/U12)-1,0) -> 0 | X12: =IFERROR(VLOOKUP(_xlfn.CONCAT($V$3,"_",B12,"_",$U$2,"_",Parámetros!$C$6),DATA_KPI_PRE!A:F,6,FALSE),0) -> 0 | Y12: =IFERROR(+(V12/X12)-1,0) -> 0 | AA12: =IFERROR(VLOOKUP(_xlfn.CONCAT($AA$3,"_",B12,"_",$AA$2,"_",Parámetros!$C$6),DATA_KPI!$A:$H,6,FALSE),0) -> 0 | AB12: =IFERROR(VLOOKUP(_xlfn.CONCAT($AB$3,"_",B12,"_",$AA$2,"_",Parámetros!$C$6),DATA_KPI!$A:$H,6,FALSE),0) -> 0 | AC12: =IFERROR(+(AB12/AA12)-1,0) -> 0 | AD12: =IFERROR(VLOOKUP(_xlfn.CONCAT($AB$3,"_",B12,"_",$AA$2,"_",Parámetros!$C$6),DATA_KPI_PRE!A:F,6,FALSE),0) -> 0 | AE12: =IFERROR(+(AB12/AD12)-1,0) -> 0 | AG12: =IFERROR(VLOOKUP(_xlfn.CONCAT($AG$3,"_",B12,"_",$AG$2,"_",Parámetros!$C$6),DATA_KPI!$A:$H,6,FALSE),0) -> 0 | AH12: =IFERROR(VLOOKUP(_xlfn.CONCAT($AH$3,"_",B12,"_",$AG$2,"_",Parámetros!$C$6),DATA_KPI!$A:$H,6,FALSE),0) -> 0 | AI12: =IFERROR(+(AH12/AG12)-1,0) -> 0 | AJ12: =IFERROR(VLOOKUP(_xlfn.CONCAT($AH$3,"_",B12,"_",$AG$2,"_",Parámetros!$C$6),DATA_KPI_PRE!A:F,6,FALSE),0) -> 0 | AK12: =IFERROR(+(AH12/AJ12)-1,0) -> 0 | AM12: =IFERROR(VLOOKUP(_xlfn.CONCAT($AM$3,"_",B12,"_",$AM$2,"_",Parámetros!$C$6),DATA_KPI!$A:$H,6,FALSE),0) -> 0 | AN12: =IFERROR(VLOOKUP(_xlfn.CONCAT($AN$3,"_",B12,"_",$AM$2,"_",Parámetros!$C$6),DATA_KPI!$A:$H,6,FALSE),0) -> 0 | AO12: =IFERROR(+AN12/AM12,0) -> 0 | AP12: =IFERROR(VLOOKUP(_xlfn.CONCAT($AN$3,"_",B12,"_",$AM$2,"_",Parámetros!$C$6),DATA_KPI_PRE!A:F,6,FALSE),0) -> 0 | AQ12: =IFERROR(+(AN12/AP12)-1,0) -> 0 | AS12: =J12/D12 -> 0.061398649 | AT12: =P12/D12 -> 0.93860135 | AU12: =V12/D12 -> 0 | AV12: =AB12/D12 -> 0 | AW12: =AH12/D12 -> 0 | AX12: =AN12/D12 -> 0 | AY12: =SUM(AS12:AX12) -> 1
A13: Guadalupe | B13: =IF(IFERROR(VLOOKUP(A13,DATA_KPI!$D:$H,5,FALSE),"")="",VLOOKUP(A13,DATA_KPI_PRE!$D:$H,5,FALSE),VLOOKUP(A13,DATA_KPI!$D:$H,5,FALSE)) -> S01 | C13: =IFERROR(VLOOKUP(_xlfn.CONCAT($C$3,"_",B13,"_",$C$2,"_",Parámetros!$C$6),DATA_KPI!$A:$H,6,FALSE),0) -> 12117822 | D13: =IFERROR(VLOOKUP(_xlfn.CONCAT($D$3,"_",B13,"_",$C$2,"_",Parámetros!$C$6),DATA_KPI!A:H,6,FALSE),0) -> 11568047 | E13: =IFERROR(+(D13/C13)-1,0) -> -0.045369166 | F13: =IFERROR(VLOOKUP(_xlfn.CONCAT($D$3,"_",B13,"_",$C$2,"_",Parámetros!$C$6),DATA_KPI_PRE!$A:$F,6,FALSE),0) -> 13694109 | G13: =IFERROR(+(D13/F13)-1,0) -> -0.1552538 | I13: =IFERROR(VLOOKUP(_xlfn.CONCAT($I$3,"_",B13,"_",$I$2,"_",Parámetros!$C$6),DATA_KPI!$A:$H,6,FALSE),0) -> 5642972.6 | J13: =IFERROR(VLOOKUP(_xlfn.CONCAT($J$3,"_",B13,"_",$I$2,"_",Parámetros!$C$6),DATA_KPI!$A:$H,6,FALSE),0) -> 6133559.1 | K13: =IFERROR(+(J13/I13)-1,0) -> 0.08693761 | L13: =IFERROR(VLOOKUP(_xlfn.CONCAT($J$3,"_",B13,"_",$I$2,"_",Parámetros!$C$6),DATA_KPI_PRE!A:F,6,FALSE),0) -> 5894147.9 | M13: =IFERROR(+(J13/L13)-1,0) -> 0.040618454 | O13: =IFERROR(VLOOKUP(_xlfn.CONCAT($O$3,"_",B13,"_",$O$2,"_",Parámetros!$C$6),DATA_KPI!$A:$H,6,FALSE),0) -> 875267.69 | P13: =IFERROR(VLOOKUP(_xlfn.CONCAT($P$3,"_",B13,"_",$O$2,"_",Parámetros!$C$6),DATA_KPI!$A:$H,6,FALSE),0) -> 567968.84 | Q13: =IFERROR(+(P13/O13)-1,0) -> -0.35109128 | R13: =IFERROR(VLOOKUP(_xlfn.CONCAT($P$3,"_",B13,"_",$O$2,"_",Parámetros!$C$6),DATA_KPI_PRE!A:F,6,FALSE),0) -> 865488.09 | S13: =IFERROR(+(P13/R13)-1,0) -> -0.34375892 | U13: =IFERROR(VLOOKUP(_xlfn.CONCAT($U$3,"_",B13,"_",$U$2,"_",Parámetros!$C$6),DATA_KPI!$A:$H,6,FALSE),0) -> 688973.85 | V13: =IFERROR(VLOOKUP(_xlfn.CONCAT($V$3,"_",B13,"_",$U$2,"_",Parámetros!$C$6),DATA_KPI!$A:$H,6,FALSE),0) -> 690329.44 | W13: =IFERROR(+(V13/U13)-1,0) -> 0.0019675493 | X13: =IFERROR(VLOOKUP(_xlfn.CONCAT($V$3,"_",B13,"_",$U$2,"_",Parámetros!$C$6),DATA_KPI_PRE!A:F,6,FALSE),0) -> 774140.85 | Y13: =IFERROR(+(V13/X13)-1,0) -> -0.10826378 | AA13: =IFERROR(VLOOKUP(_xlfn.CONCAT($AA$3,"_",B13,"_",$AA$2,"_",Parámetros!$C$6),DATA_KPI!$A:$H,6,FALSE),0) -> 880011.86 | AB13: =IFERROR(VLOOKUP(_xlfn.CONCAT($AB$3,"_",B13,"_",$AA$2,"_",Parámetros!$C$6),DATA_KPI!$A:$H,6,FALSE),0) -> 606507.33 | AC13: =IFERROR(+(AB13/AA13)-1,0) -> -0.31079641 | AD13: =IFERROR(VLOOKUP(_xlfn.CONCAT($AB$3,"_",B13,"_",$AA$2,"_",Parámetros!$C$6),DATA_KPI_PRE!A:F,6,FALSE),0) -> 1332466.5 | AE13: =IFERROR(+(AB13/AD13)-1,0) -> -0.54482357 | AG13: =IFERROR(VLOOKUP(_xlfn.CONCAT($AG$3,"_",B13,"_",$AG$2,"_",Parámetros!$C$6),DATA_KPI!$A:$H,6,FALSE),0) -> 3967119.2 | AH13: =IFERROR(VLOOKUP(_xlfn.CONCAT($AH$3,"_",B13,"_",$AG$2,"_",Parámetros!$C$6),DATA_KPI!$A:$H,6,FALSE),0) -> 3512606.6 | AI13: =IFERROR(+(AH13/AG13)-1,0) -> -0.11456992 | AJ13: =IFERROR(VLOOKUP(_xlfn.CONCAT($AH$3,"_",B13,"_",$AG$2,"_",Parámetros!$C$6),DATA_KPI_PRE!A:F,6,FALSE),0) -> 4699120.7 | AK13: =IFERROR(+(AH13/AJ13)-1,0) -> -0.25249704 | AM13: =IFERROR(VLOOKUP(_xlfn.CONCAT($AM$3,"_",B13,"_",$AM$2,"_",Parámetros!$C$6),DATA_KPI!$A:$H,6,FALSE),0) -> 63476.94 | AN13: =IFERROR(VLOOKUP(_xlfn.CONCAT($AN$3,"_",B13,"_",$AM$2,"_",Parámetros!$C$6),DATA_KPI!$A:$H,6,FALSE),0) -> 57075.23 | AO13: =IFERROR(+AN13/AM13,0) -> 0.89914905 | AP13: =IFERROR(VLOOKUP(_xlfn.CONCAT($AN$3,"_",B13,"_",$AM$2,"_",Parámetros!$C$6),DATA_KPI_PRE!A:F,6,FALSE),0) -> 128745.02 | AQ13: =IFERROR(+(AN13/AP13)-1,0) -> -0.55668008 | AS13: =J13/D13 -> 0.53021563 | AT13: =P13/D13 -> 0.049098077 | AU13: =V13/D13 -> 0.059675541 | AV13: =AB13/D13 -> 0.052429537 | AW13: =AH13/D13 -> 0.30364734 | AX13: =AN13/D13 -> 0.0049338693 | AY13: =SUM(AS13:AX13) -> 1
A14: Heredia | B14: =IF(IFERROR(VLOOKUP(A14,DATA_KPI!$D:$H,5,FALSE),"")="",VLOOKUP(A14,DATA_KPI_PRE!$D:$H,5,FALSE),VLOOKUP(A14,DATA_KPI!$D:$H,5,FALSE)) -> S13 | C14: =IFERROR(VLOOKUP(_xlfn.CONCAT($C$3,"_",B14,"_",$C$2,"_",Parámetros!$C$6),DATA_KPI!$A:$H,6,FALSE),0) -> 14434485 | D14: =IFERROR(VLOOKUP(_xlfn.CONCAT($D$3,"_",B14,"_",$C$2,"_",Parámetros!$C$6),DATA_KPI!A:H,6,FALSE),0) -> 13567277 | E14: =IFERROR(+(D14/C14)-1,0) -> -0.060078883 | F14: =IFERROR(VLOOKUP(_xlfn.CONCAT($D$3,"_",B14,"_",$C$2,"_",Parámetros!$C$6),DATA_KPI_PRE!$A:$F,6,FALSE),0) -> 14445055 | G14: =IFERROR(+(D14/F14)-1,0) -> -0.060766701 | I14: =IFERROR(VLOOKUP(_xlfn.CONCAT($I$3,"_",B14,"_",$I$2,"_",Parámetros!$C$6),DATA_KPI!$A:$H,6,FALSE),0) -> 6589035 | J14: =IFERROR(VLOOKUP(_xlfn.CONCAT($J$3,"_",B14,"_",$I$2,"_",Parámetros!$C$6),DATA_KPI!$A:$H,6,FALSE),0) -> 5309996.9 | K14: =IFERROR(+(J14/I14)-1,0) -> -0.19411615 | L14: =IFERROR(VLOOKUP(_xlfn.CONCAT($J$3,"_",B14,"_",$I$2,"_",Parámetros!$C$6),DATA_KPI_PRE!A:F,6,FALSE),0) -> 6674564.2 | M14: =IFERROR(+(J14/L14)-1,0) -> -0.2044429 | O14: =IFERROR(VLOOKUP(_xlfn.CONCAT($O$3,"_",B14,"_",$O$2,"_",Parámetros!$C$6),DATA_KPI!$A:$H,6,FALSE),0) -> 770192.54 | P14: =IFERROR(VLOOKUP(_xlfn.CONCAT($P$3,"_",B14,"_",$O$2,"_",Parámetros!$C$6),DATA_KPI!$A:$H,6,FALSE),0) -> 1202525.4 | Q14: =IFERROR(+(P14/O14)-1,0) -> 0.56133091 | R14: =IFERROR(VLOOKUP(_xlfn.CONCAT($P$3,"_",B14,"_",$O$2,"_",Parámetros!$C$6),DATA_KPI_PRE!A:F,6,FALSE),0) -> 570090.33 | S14: =IFERROR(+(P14/R14)-1,0) -> 1.1093594 | U14: =IFERROR(VLOOKUP(_xlfn.CONCAT($U$3,"_",B14,"_",$U$2,"_",Parámetros!$C$6),DATA_KPI!$A:$H,6,FALSE),0) -> 156716.84 | V14: =IFERROR(VLOOKUP(_xlfn.CONCAT($V$3,"_",B14,"_",$U$2,"_",Parámetros!$C$6),DATA_KPI!$A:$H,6,FALSE),0) -> 698858.71 | W14: =IFERROR(+(V14/U14)-1,0) -> 3.4593721 | X14: =IFERROR(VLOOKUP(_xlfn.CONCAT($V$3,"_",B14,"_",$U$2,"_",Parámetros!$C$6),DATA_KPI_PRE!A:F,6,FALSE),0) -> 340125.19 | Y14: =IFERROR(+(V14/X14)-1,0) -> 1.0547102 | AA14: =IFERROR(VLOOKUP(_xlfn.CONCAT($AA$3,"_",B14,"_",$AA$2,"_",Parámetros!$C$6),DATA_KPI!$A:$H,6,FALSE),0) -> 628834.94 | AB14: =IFERROR(VLOOKUP(_xlfn.CONCAT($AB$3,"_",B14,"_",$AA$2,"_",Parámetros!$C$6),DATA_KPI!$A:$H,6,FALSE),0) -> 319495.66 | AC14: =IFERROR(+(AB14/AA14)-1,0) -> -0.49192445 | AD14: =IFERROR(VLOOKUP(_xlfn.CONCAT($AB$3,"_",B14,"_",$AA$2,"_",Parámetros!$C$6),DATA_KPI_PRE!A:F,6,FALSE),0) -> 602978.82 | AE14: =IFERROR(+(AB14/AD14)-1,0) -> -0.47013784 | AG14: =IFERROR(VLOOKUP(_xlfn.CONCAT($AG$3,"_",B14,"_",$AG$2,"_",Parámetros!$C$6),DATA_KPI!$A:$H,6,FALSE),0) -> 6272369.1 | AH14: =IFERROR(VLOOKUP(_xlfn.CONCAT($AH$3,"_",B14,"_",$AG$2,"_",Parámetros!$C$6),DATA_KPI!$A:$H,6,FALSE),0) -> 5944630.8 | AI14: =IFERROR(+(AH14/AG14)-1,0) -> -0.052251118 | AJ14: =IFERROR(VLOOKUP(_xlfn.CONCAT($AH$3,"_",B14,"_",$AG$2,"_",Parámetros!$C$6),DATA_KPI_PRE!A:F,6,FALSE),0) -> 6238807.7 | AK14: =IFERROR(+(AH14/AJ14)-1,0) -> -0.047152742 | AM14: =IFERROR(VLOOKUP(_xlfn.CONCAT($AM$3,"_",B14,"_",$AM$2,"_",Parámetros!$C$6),DATA_KPI!$A:$H,6,FALSE),0) -> 17336.28 | AN14: =IFERROR(VLOOKUP(_xlfn.CONCAT($AN$3,"_",B14,"_",$AM$2,"_",Parámetros!$C$6),DATA_KPI!$A:$H,6,FALSE),0) -> 91769.47 | AO14: =IFERROR(+AN14/AM14,0) -> 5.2934926 | AP14: =IFERROR(VLOOKUP(_xlfn.CONCAT($AN$3,"_",B14,"_",$AM$2,"_",Parámetros!$C$6),DATA_KPI_PRE!A:F,6,FALSE),0) -> 18489.1 | AQ14: =IFERROR(+(AN14/AP14)-1,0) -> 3.9634363 | AS14: =J14/D14 -> 0.39138265 | AT14: =P14/D14 -> 0.08863425 | AU14: =V14/D14 -> 0.05151061 | AV14: =AB14/D14 -> 0.023548989 | AW14: =AH14/D14 -> 0.43815947 | AX14: =AN14/D14 -> 0.0067640301 | AY14: =SUM(AS14:AX14) -> 1
A15: Lincoln | B15: =IF(IFERROR(VLOOKUP(A15,DATA_KPI!$D:$H,5,FALSE),"")="",VLOOKUP(A15,DATA_KPI_PRE!$D:$H,5,FALSE),VLOOKUP(A15,DATA_KPI!$D:$H,5,FALSE)) -> S32 | C15: =IFERROR(VLOOKUP(_xlfn.CONCAT($C$3,"_",B15,"_",$C$2,"_",Parámetros!$C$6),DATA_KPI!$A:$H,6,FALSE),0) -> 15957425 | D15: =IFERROR(VLOOKUP(_xlfn.CONCAT($D$3,"_",B15,"_",$C$2,"_",Parámetros!$C$6),DATA_KPI!A:H,6,FALSE),0) -> 15917707 | E15: =IFERROR(+(D15/C15)-1,0) -> -0.0024889886 | F15: =IFERROR(VLOOKUP(_xlfn.CONCAT($D$3,"_",B15,"_",$C$2,"_",Parámetros!$C$6),DATA_KPI_PRE!$A:$F,6,FALSE),0) -> 15968373 | G15: =IFERROR(+(D15/F15)-1,0) -> -0.0031728493 | I15: =IFERROR(VLOOKUP(_xlfn.CONCAT($I$3,"_",B15,"_",$I$2,"_",Parámetros!$C$6),DATA_KPI!$A:$H,6,FALSE),0) -> 13081281 | J15: =IFERROR(VLOOKUP(_xlfn.CONCAT($J$3,"_",B15,"_",$I$2,"_",Parámetros!$C$6),DATA_KPI!$A:$H,6,FALSE),0) -> 12959948 | K15: =IFERROR(+(J15/I15)-1,0) -> -0.0092752798 | L15: =IFERROR(VLOOKUP(_xlfn.CONCAT($J$3,"_",B15,"_",$I$2,"_",Parámetros!$C$6),DATA_KPI_PRE!A:F,6,FALSE),0) -> 13030921 | M15: =IFERROR(+(J15/L15)-1,0) -> -0.0054464571 | O15: =IFERROR(VLOOKUP(_xlfn.CONCAT($O$3,"_",B15,"_",$O$2,"_",Parámetros!$C$6),DATA_KPI!$A:$H,6,FALSE),0) -> 513531.23 | P15: =IFERROR(VLOOKUP(_xlfn.CONCAT($P$3,"_",B15,"_",$O$2,"_",Parámetros!$C$6),DATA_KPI!$A:$H,6,FALSE),0) -> 340772.56 | Q15: =IFERROR(+(P15/O15)-1,0) -> -0.33641317 | R15: =IFERROR(VLOOKUP(_xlfn.CONCAT($P$3,"_",B15,"_",$O$2,"_",Parámetros!$C$6),DATA_KPI_PRE!A:F,6,FALSE),0) -> 619333.61 | S15: =IFERROR(+(P15/R15)-1,0) -> -0.44977545 | U15: =IFERROR(VLOOKUP(_xlfn.CONCAT($U$3,"_",B15,"_",$U$2,"_",Parámetros!$C$6),DATA_KPI!$A:$H,6,FALSE),0) -> 0 | V15: =IFERROR(VLOOKUP(_xlfn.CONCAT($V$3,"_",B15,"_",$U$2,"_",Parámetros!$C$6),DATA_KPI!$A:$H,6,FALSE),0) -> 0 | W15: =IFERROR(+(V15/U15)-1,0) -> 0 | X15: =IFERROR(VLOOKUP(_xlfn.CONCAT($V$3,"_",B15,"_",$U$2,"_",Parámetros!$C$6),DATA_KPI_PRE!A:F,6,FALSE),0) -> 0 | Y15: =IFERROR(+(V15/X15)-1,0) -> 0 | AA15: =IFERROR(VLOOKUP(_xlfn.CONCAT($AA$3,"_",B15,"_",$AA$2,"_",Parámetros!$C$6),DATA_KPI!$A:$H,6,FALSE),0) -> 0 | AB15: =IFERROR(VLOOKUP(_xlfn.CONCAT($AB$3,"_",B15,"_",$AA$2,"_",Parámetros!$C$6),DATA_KPI!$A:$H,6,FALSE),0) -> 0 | AC15: =IFERROR(+(AB15/AA15)-1,0) -> 0 | AD15: =IFERROR(VLOOKUP(_xlfn.CONCAT($AB$3,"_",B15,"_",$AA$2,"_",Parámetros!$C$6),DATA_KPI_PRE!A:F,6,FALSE),0) -> 0 | AE15: =IFERROR(+(AB15/AD15)-1,0) -> 0 | AG15: =IFERROR(VLOOKUP(_xlfn.CONCAT($AG$3,"_",B15,"_",$AG$2,"_",Parámetros!$C$6),DATA_KPI!$A:$H,6,FALSE),0) -> 2362613.2 | AH15: =IFERROR(VLOOKUP(_xlfn.CONCAT($AH$3,"_",B15,"_",$AG$2,"_",Parámetros!$C$6),DATA_KPI!$A:$H,6,FALSE),0) -> 2616986.6 | AI15: =IFERROR(+(AH15/AG15)-1,0) -> 0.1076661 | AJ15: =IFERROR(VLOOKUP(_xlfn.CONCAT($AH$3,"_",B15,"_",$AG$2,"_",Parámetros!$C$6),DATA_KPI_PRE!A:F,6,FALSE),0) -> 2318118.4 | AK15: =IFERROR(+(AH15/AJ15)-1,0) -> 0.12892705 | AM15: =IFERROR(VLOOKUP(_xlfn.CONCAT($AM$3,"_",B15,"_",$AM$2,"_",Parámetros!$C$6),DATA_KPI!$A:$H,6,FALSE),0) -> 0 | AN15: =IFERROR(VLOOKUP(_xlfn.CONCAT($AN$3,"_",B15,"_",$AM$2,"_",Parámetros!$C$6),DATA_KPI!$A:$H,6,FALSE),0) -> 0 | AO15: =IFERROR(+AN15/AM15,0) -> 0 | AP15: =IFERROR(VLOOKUP(_xlfn.CONCAT($AN$3,"_",B15,"_",$AM$2,"_",Parámetros!$C$6),DATA_KPI_PRE!A:F,6,FALSE),0) -> 0 | AQ15: =IFERROR(+(AN15/AP15)-1,0) -> 0 | AS15: =J15/D15 -> 0.81418435 | AT15: =P15/D15 -> 0.021408394 | AU15: =V15/D15 -> 0 | AV15: =AB15/D15 -> 0 | AW15: =AH15/D15 -> 0.16440725 | AX15: =AN15/D15 -> 0 | AY15: =SUM(AS15:AX15) -> 1
A16: Multiplaza del Este | B16: =IF(IFERROR(VLOOKUP(A16,DATA_KPI!$D:$H,5,FALSE),"")="",VLOOKUP(A16,DATA_KPI_PRE!$D:$H,5,FALSE),VLOOKUP(A16,DATA_KPI!$D:$H,5,FALSE)) -> S31 | C16: =IFERROR(VLOOKUP(_xlfn.CONCAT($C$3,"_",B16,"_",$C$2,"_",Parámetros!$C$6),DATA_KPI!$A:$H,6,FALSE),0) -> 26637318 | D16: =IFERROR(VLOOKUP(_xlfn.CONCAT($D$3,"_",B16,"_",$C$2,"_",Parámetros!$C$6),DATA_KPI!A:H,6,FALSE),0) -> 22481850 | E16: =IFERROR(+(D16/C16)-1,0) -> -0.15600174 | F16: =IFERROR(VLOOKUP(_xlfn.CONCAT($D$3,"_",B16,"_",$C$2,"_",Parámetros!$C$6),DATA_KPI_PRE!$A:$F,6,FALSE),0) -> 25133112 | G16: =IFERROR(+(D16/F16)-1,0) -> -0.10548879 | I16: =IFERROR(VLOOKUP(_xlfn.CONCAT($I$3,"_",B16,"_",$I$2,"_",Parámetros!$C$6),DATA_KPI!$A:$H,6,FALSE),0) -> 24086027 | J16: =IFERROR(VLOOKUP(_xlfn.CONCAT($J$3,"_",B16,"_",$I$2,"_",Parámetros!$C$6),DATA_KPI!$A:$H,6,FALSE),0) -> 20186948 | K16: =IFERROR(+(J16/I16)-1,0) -> -0.16188136 | L16: =IFERROR(VLOOKUP(_xlfn.CONCAT($J$3,"_",B16,"_",$I$2,"_",Parámetros!$C$6),DATA_KPI_PRE!A:F,6,FALSE),0) -> 22056560 | M16: =IFERROR(+(J16/L16)-1,0) -> -0.084764414 | O16: =IFERROR(VLOOKUP(_xlfn.CONCAT($O$3,"_",B16,"_",$O$2,"_",Parámetros!$C$6),DATA_KPI!$A:$H,6,FALSE),0) -> 1000616.7 | P16: =IFERROR(VLOOKUP(_xlfn.CONCAT($P$3,"_",B16,"_",$O$2,"_",Parámetros!$C$6),DATA_KPI!$A:$H,6,FALSE),0) -> 603661.88 | Q16: =IFERROR(+(P16/O16)-1,0) -> -0.39671019 | R16: =IFERROR(VLOOKUP(_xlfn.CONCAT($P$3,"_",B16,"_",$O$2,"_",Parámetros!$C$6),DATA_KPI_PRE!A:F,6,FALSE),0) -> 1210923.7 | S16: =IFERROR(+(P16/R16)-1,0) -> -0.50148646 | U16: =IFERROR(VLOOKUP(_xlfn.CONCAT($U$3,"_",B16,"_",$U$2,"_",Parámetros!$C$6),DATA_KPI!$A:$H,6,FALSE),0) -> 0 | V16: =IFERROR(VLOOKUP(_xlfn.CONCAT($V$3,"_",B16,"_",$U$2,"_",Parámetros!$C$6),DATA_KPI!$A:$H,6,FALSE),0) -> 0 | W16: =IFERROR(+(V16/U16)-1,0) -> 0 | X16: =IFERROR(VLOOKUP(_xlfn.CONCAT($V$3,"_",B16,"_",$U$2,"_",Parámetros!$C$6),DATA_KPI_PRE!A:F,6,FALSE),0) -> 0 | Y16: =IFERROR(+(V16/X16)-1,0) -> 0 | AA16: =IFERROR(VLOOKUP(_xlfn.CONCAT($AA$3,"_",B16,"_",$AA$2,"_",Parámetros!$C$6),DATA_KPI!$A:$H,6,FALSE),0) -> 0 | AB16: =IFERROR(VLOOKUP(_xlfn.CONCAT($AB$3,"_",B16,"_",$AA$2,"_",Parámetros!$C$6),DATA_KPI!$A:$H,6,FALSE),0) -> 0 | AC16: =IFERROR(+(AB16/AA16)-1,0) -> 0 | AD16: =IFERROR(VLOOKUP(_xlfn.CONCAT($AB$3,"_",B16,"_",$AA$2,"_",Parámetros!$C$6),DATA_KPI_PRE!A:F,6,FALSE),0) -> 0 | AE16: =IFERROR(+(AB16/AD16)-1,0) -> 0 | AG16: =IFERROR(VLOOKUP(_xlfn.CONCAT($AG$3,"_",B16,"_",$AG$2,"_",Parámetros!$C$6),DATA_KPI!$A:$H,6,FALSE),0) -> 1550674.8 | AH16: =IFERROR(VLOOKUP(_xlfn.CONCAT($AH$3,"_",B16,"_",$AG$2,"_",Parámetros!$C$6),DATA_KPI!$A:$H,6,FALSE),0) -> 1691240.3 | AI16: =IFERROR(+(AH16/AG16)-1,0) -> 0.090647968 | AJ16: =IFERROR(VLOOKUP(_xlfn.CONCAT($AH$3,"_",B16,"_",$AG$2,"_",Parámetros!$C$6),DATA_KPI_PRE!A:F,6,FALSE),0) -> 1865628.8 | AK16: =IFERROR(+(AH16/AJ16)-1,0) -> -0.093474342 | AM16: =IFERROR(VLOOKUP(_xlfn.CONCAT($AM$3,"_",B16,"_",$AM$2,"_",Parámetros!$C$6),DATA_KPI!$A:$H,6,FALSE),0) -> 0 | AN16: =IFERROR(VLOOKUP(_xlfn.CONCAT($AN$3,"_",B16,"_",$AM$2,"_",Parámetros!$C$6),DATA_KPI!$A:$H,6,FALSE),0) -> 0 | AO16: =IFERROR(+AN16/AM16,0) -> 0 | AP16: =IFERROR(VLOOKUP(_xlfn.CONCAT($AN$3,"_",B16,"_",$AM$2,"_",Parámetros!$C$6),DATA_KPI_PRE!A:F,6,FALSE),0) -> 0 | AQ16: =IFERROR(+(AN16/AP16)-1,0) -> 0 | AS16: =J16/D16 -> 0.89792201 | AT16: =P16/D16 -> 0.026851076 | AU16: =V16/D16 -> 0 | AV16: =AB16/D16 -> 0 | AW16: =AH16/D16 -> 0.075226919 | AX16: =AN16/D16 -> 0 | AY16: =SUM(AS16:AX16) -> 1
A17: Multiplaza Escazú | B17: =IF(IFERROR(VLOOKUP(A17,DATA_KPI!$D:$H,5,FALSE),"")="",VLOOKUP(A17,DATA_KPI_PRE!$D:$H,5,FALSE),VLOOKUP(A17,DATA_KPI!$D:$H,5,FALSE)) -> S06 | C17: =IFERROR(VLOOKUP(_xlfn.CONCAT($C$3,"_",B17,"_",$C$2,"_",Parámetros!$C$6),DATA_KPI!$A:$H,6,FALSE),0) -> 29035379 | D17: =IFERROR(VLOOKUP(_xlfn.CONCAT($D$3,"_",B17,"_",$C$2,"_",Parámetros!$C$6),DATA_KPI!A:H,6,FALSE),0) -> 28552513 | E17: =IFERROR(+(D17/C17)-1,0) -> -0.016630254 | F17: =IFERROR(VLOOKUP(_xlfn.CONCAT($D$3,"_",B17,"_",$C$2,"_",Parámetros!$C$6),DATA_KPI_PRE!$A:$F,6,FALSE),0) -> 28501963 | G17: =IFERROR(+(D17/F17)-1,0) -> 0.0017735669 | I17: =IFERROR(VLOOKUP(_xlfn.CONCAT($I$3,"_",B17,"_",$I$2,"_",Parámetros!$C$6),DATA_KPI!$A:$H,6,FALSE),0) -> 26943837 | J17: =IFERROR(VLOOKUP(_xlfn.CONCAT($J$3,"_",B17,"_",$I$2,"_",Parámetros!$C$6),DATA_KPI!$A:$H,6,FALSE),0) -> 26519643 | K17: =IFERROR(+(J17/I17)-1,0) -> -0.015743641 | L17: =IFERROR(VLOOKUP(_xlfn.CONCAT($J$3,"_",B17,"_",$I$2,"_",Parámetros!$C$6),DATA_KPI_PRE!A:F,6,FALSE),0) -> 26010396 | M17: =IFERROR(+(J17/L17)-1,0) -> 0.019578588 | O17: =IFERROR(VLOOKUP(_xlfn.CONCAT($O$3,"_",B17,"_",$O$2,"_",Parámetros!$C$6),DATA_KPI!$A:$H,6,FALSE),0) -> 686813.73 | P17: =IFERROR(VLOOKUP(_xlfn.CONCAT($P$3,"_",B17,"_",$O$2,"_",Parámetros!$C$6),DATA_KPI!$A:$H,6,FALSE),0) -> 353978.23 | Q17: =IFERROR(+(P17/O17)-1,0) -> -0.4846081 | R17: =IFERROR(VLOOKUP(_xlfn.CONCAT($P$3,"_",B17,"_",$O$2,"_",Parámetros!$C$6),DATA_KPI_PRE!A:F,6,FALSE),0) -> 976033.84 | S17: =IFERROR(+(P17/R17)-1,0) -> -0.63732996 | U17: =IFERROR(VLOOKUP(_xlfn.CONCAT($U$3,"_",B17,"_",$U$2,"_",Parámetros!$C$6),DATA_KPI!$A:$H,6,FALSE),0) -> 0 | V17: =IFERROR(VLOOKUP(_xlfn.CONCAT($V$3,"_",B17,"_",$U$2,"_",Parámetros!$C$6),DATA_KPI!$A:$H,6,FALSE),0) -> 0 | W17: =IFERROR(+(V17/U17)-1,0) -> 0 | X17: =IFERROR(VLOOKUP(_xlfn.CONCAT($V$3,"_",B17,"_",$U$2,"_",Parámetros!$C$6),DATA_KPI_PRE!A:F,6,FALSE),0) -> 0 | Y17: =IFERROR(+(V17/X17)-1,0) -> 0 | AA17: =IFERROR(VLOOKUP(_xlfn.CONCAT($AA$3,"_",B17,"_",$AA$2,"_",Parámetros!$C$6),DATA_KPI!$A:$H,6,FALSE),0) -> 0 | AB17: =IFERROR(VLOOKUP(_xlfn.CONCAT($AB$3,"_",B17,"_",$AA$2,"_",Parámetros!$C$6),DATA_KPI!$A:$H,6,FALSE),0) -> 0 | AC17: =IFERROR(+(AB17/AA17)-1,0) -> 0 | AD17: =IFERROR(VLOOKUP(_xlfn.CONCAT($AB$3,"_",B17,"_",$AA$2,"_",Parámetros!$C$6),DATA_KPI_PRE!A:F,6,FALSE),0) -> 0 | AE17: =IFERROR(+(AB17/AD17)-1,0) -> 0 | AG17: =IFERROR(VLOOKUP(_xlfn.CONCAT($AG$3,"_",B17,"_",$AG$2,"_",Parámetros!$C$6),DATA_KPI!$A:$H,6,FALSE),0) -> 1404727.9 | AH17: =IFERROR(VLOOKUP(_xlfn.CONCAT($AH$3,"_",B17,"_",$AG$2,"_",Parámetros!$C$6),DATA_KPI!$A:$H,6,FALSE),0) -> 1678891.8 | AI17: =IFERROR(+(AH17/AG17)-1,0) -> 0.19517221 | AJ17: =IFERROR(VLOOKUP(_xlfn.CONCAT($AH$3,"_",B17,"_",$AG$2,"_",Parámetros!$C$6),DATA_KPI_PRE!A:F,6,FALSE),0) -> 1515532.9 | AK17: =IFERROR(+(AH17/AJ17)-1,0) -> 0.10778974 | AM17: =IFERROR(VLOOKUP(_xlfn.CONCAT($AM$3,"_",B17,"_",$AM$2,"_",Parámetros!$C$6),DATA_KPI!$A:$H,6,FALSE),0) -> 0 | AN17: =IFERROR(VLOOKUP(_xlfn.CONCAT($AN$3,"_",B17,"_",$AM$2,"_",Parámetros!$C$6),DATA_KPI!$A:$H,6,FALSE),0) -> 0 | AO17: =IFERROR(+AN17/AM17,0) -> 0 | AP17: =IFERROR(VLOOKUP(_xlfn.CONCAT($AN$3,"_",B17,"_",$AM$2,"_",Parámetros!$C$6),DATA_KPI_PRE!A:F,6,FALSE),0) -> 0 | AQ17: =IFERROR(+(AN17/AP17)-1,0) -> 0 | AS17: =J17/D17 -> 0.92880241 | AT17: =P17/D17 -> 0.012397446 | AU17: =V17/D17 -> 0 | AV17: =AB17/D17 -> 0 | AW17: =AH17/D17 -> 0.05880014 | AX17: =AN17/D17 -> 0 | AY17: =SUM(AS17:AX17) -> 1
... A20: Pinares | B20: =IF(IFERROR(VLOOKUP(A20,DATA_KPI!$D:$H,5,FALSE),"")="",VLOOKUP(A20,DATA_KPI_PRE!$D:$H,5,FALSE),VLOOKUP(A20,DATA_KPI!$D:$H,5,FALSE)) -> S67 | C20: =IFERROR(VLOOKUP(_xlfn.CONCAT($C$3,"_",B20,"_",$C$2,"_",Parámetros!$C$6),DATA_KPI!$A:$H,6,FALSE),0) -> 19320580 | D20: =IFERROR(VLOOKUP(_xlfn.CONCAT($D$3,"_",B20,"_",$C$2,"_",Parámetros!$C$6),DATA_KPI!A:H,6,FALSE),0) -> 18079547 | E20: =IFERROR(+(D20/C20)-1,0) -> -0.064233693 | F20: =IFERROR(VLOOKUP(_xlfn.CONCAT($D$3,"_",B20,"_",$C$2,"_",Parámetros!$C$6),DATA_KPI_PRE!$A:$F,6,FALSE),0) -> 18041672 | G20: =IFERROR(+(D20/F20)-1,0) -> 0.0020993289 | I20: =IFERROR(VLOOKUP(_xlfn.CONCAT($I$3,"_",B20,"_",$I$2,"_",Parámetros!$C$6),DATA_KPI!$A:$H,6,FALSE),0) -> 10013003 | J20: =IFERROR(VLOOKUP(_xlfn.CONCAT($J$3,"_",B20,"_",$I$2,"_",Parámetros!$C$6),DATA_KPI!$A:$H,6,FALSE),0) -> 9468990.5 | K20: =IFERROR(+(J20/I20)-1,0) -> -0.054330588 | L20: =IFERROR(VLOOKUP(_xlfn.CONCAT($J$3,"_",B20,"_",$I$2,"_",Parámetros!$C$6),DATA_KPI_PRE!A:F,6,FALSE),0) -> 9191050 | M20: =IFERROR(+(J20/L20)-1,0) -> 0.030240349 | O20: =IFERROR(VLOOKUP(_xlfn.CONCAT($O$3,"_",B20,"_",$O$2,"_",Parámetros!$C$6),DATA_KPI!$A:$H,6,FALSE),0) -> 1385450.6 | P20: =IFERROR(VLOOKUP(_xlfn.CONCAT($P$3,"_",B20,"_",$O$2,"_",Parámetros!$C$6),DATA_KPI!$A:$H,6,FALSE),0) -> 1119129.9 | Q20: =IFERROR(+(P20/O20)-1,0) -> -0.1922268 | R20: =IFERROR(VLOOKUP(_xlfn.CONCAT($P$3,"_",B20,"_",$O$2,"_",Parámetros!$C$6),DATA_KPI_PRE!A:F,6,FALSE),0) -> 1421691.5 | S20: =IFERROR(+(P20/R20)-1,0) -> -0.21281808 | U20: =IFERROR(VLOOKUP(_xlfn.CONCAT($U$3,"_",B20,"_",$U$2,"_",Parámetros!$C$6),DATA_KPI!$A:$H,6,FALSE),0) -> 0 | V20: =IFERROR(VLOOKUP(_xlfn.CONCAT($V$3,"_",B20,"_",$U$2,"_",Parámetros!$C$6),DATA_KPI!$A:$H,6,FALSE),0) -> 0 | W20: =IFERROR(+(V20/U20)-1,0) -> 0 | X20: =IFERROR(VLOOKUP(_xlfn.CONCAT($V$3,"_",B20,"_",$U$2,"_",Parámetros!$C$6),DATA_KPI_PRE!A:F,6,FALSE),0) -> 0 | Y20: =IFERROR(+(V20/X20)-1,0) -> 0 | AA20: =IFERROR(VLOOKUP(_xlfn.CONCAT($AA$3,"_",B20,"_",$AA$2,"_",Parámetros!$C$6),DATA_KPI!$A:$H,6,FALSE),0) -> 392752.32 | AB20: =IFERROR(VLOOKUP(_xlfn.CONCAT($AB$3,"_",B20,"_",$AA$2,"_",Parámetros!$C$6),DATA_KPI!$A:$H,6,FALSE),0) -> 257604.52 | AC20: =IFERROR(+(AB20/AA20)-1,0) -> -0.3441044 | AD20: =IFERROR(VLOOKUP(_xlfn.CONCAT($AB$3,"_",B20,"_",$AA$2,"_",Parámetros!$C$6),DATA_KPI_PRE!A:F,6,FALSE),0) -> 545513.09 | AE20: =IFERROR(+(AB20/AD20)-1,0) -> -0.52777573 | AG20: =IFERROR(VLOOKUP(_xlfn.CONCAT($AG$3,"_",B20,"_",$AG$2,"_",Parámetros!$C$6),DATA_KPI!$A:$H,6,FALSE),0) -> 7462701.2 | AH20: =IFERROR(VLOOKUP(_xlfn.CONCAT($AH$3,"_",B20,"_",$AG$2,"_",Parámetros!$C$6),DATA_KPI!$A:$H,6,FALSE),0) -> 7212804.7 | AI20: =IFERROR(+(AH20/AG20)-1,0) -> -0.03348606 | AJ20: =IFERROR(VLOOKUP(_xlfn.CONCAT($AH$3,"_",B20,"_",$AG$2,"_",Parámetros!$C$6),DATA_KPI_PRE!A:F,6,FALSE),0) -> 6829387.5 | AK20: =IFERROR(+(AH20/AJ20)-1,0) -> 0.056142262 | AM20: =IFERROR(VLOOKUP(_xlfn.CONCAT($AM$3,"_",B20,"_",$AM$2,"_",Parámetros!$C$6),DATA_KPI!$A:$H,6,FALSE),0) -> 66672.56 | AN20: =IFERROR(VLOOKUP(_xlfn.CONCAT($AN$3,"_",B20,"_",$AM$2,"_",Parámetros!$C$6),DATA_KPI!$A:$H,6,FALSE),0) -> 21017.71 | AO20: =IFERROR(+AN20/AM20,0) -> 0.31523778 | AP20: =IFERROR(VLOOKUP(_xlfn.CONCAT($AN$3,"_",B20,"_",$AM$2,"_",Parámetros!$C$6),DATA_KPI_PRE!A:F,6,FALSE),0) -> 54029.884 | AQ20: =IFERROR(+(AN20/AP20)-1,0) -> -0.61099842 | AS20: =J20/D20 -> 0.52374047 | AT20: =P20/D20 -> 0.061900325 | AU20: =V20/D20 -> 0 | AV20: =AB20/D20 -> 0.014248394 | AW20: =AH20/D20 -> 0.3989483 | AX20: =AN20/D20 -> 0.0011625131 | AY20: =SUM(AS20:AX20) -> 1
A21: Plaza Práktico | B21: S24 | C21: =IFERROR(VLOOKUP(_xlfn.CONCAT($C$3,"_",B21,"_",$C$2,"_",Parámetros!$C$6),DATA_KPI!$A:$H,6,FALSE),0) -> 9300473.1 | D21: =IFERROR(VLOOKUP(_xlfn.CONCAT($D$3,"_",B21,"_",$C$2,"_",Parámetros!$C$6),DATA_KPI!A:H,6,FALSE),0) -> 9776510.1 | E21: =IFERROR(+D21/C21,0) -> 1.0511842 | F21: =IFERROR(VLOOKUP(_xlfn.CONCAT($D$3,"_",B21,"_",$C$2,"_",Parámetros!$C$6),DATA_KPI_PRE!$A:$F,6,FALSE),0) -> 9996843.1 | G21: =IFERROR(+(D21/F21)-1,0) -> -0.022040257 | I21: =IFERROR(VLOOKUP(_xlfn.CONCAT($I$3,"_",B21,"_",$I$2,"_",Parámetros!$C$6),DATA_KPI!$A:$H,6,FALSE),0) -> 6590534.2 | J21: =IFERROR(VLOOKUP(_xlfn.CONCAT($J$3,"_",B21,"_",$I$2,"_",Parámetros!$C$6),DATA_KPI!$A:$H,6,FALSE),0) -> 6680235.6 | K21: =IFERROR(+J21/I21,0) -> 1.0136106 | L21: =IFERROR(VLOOKUP(_xlfn.CONCAT($J$3,"_",B21,"_",$I$2,"_",Parámetros!$C$6),DATA_KPI_PRE!A:F,6,FALSE),0) -> 7079792.2 | M21: =IFERROR(+(J21/L21)-1,0) -> -0.056436204 | O21: =IFERROR(VLOOKUP(_xlfn.CONCAT($O$3,"_",B21,"_",$O$2,"_",Parámetros!$C$6),DATA_KPI!$A:$H,6,FALSE),0) -> 551119.85 | P21: =IFERROR(VLOOKUP(_xlfn.CONCAT($P$3,"_",B21,"_",$O$2,"_",Parámetros!$C$6),DATA_KPI!$A:$H,6,FALSE),0) -> 335242.8 | Q21: =IFERROR(+P21/O21,0) -> 0.60829382 | R21: =IFERROR(VLOOKUP(_xlfn.CONCAT($P$3,"_",B21,"_",$O$2,"_",Parámetros!$C$6),DATA_KPI_PRE!A:F,6,FALSE),0) -> 559367.66 | S21: =IFERROR(+(P21/R21)-1,0) -> -0.40067539 | U21: =IFERROR(VLOOKUP(_xlfn.CONCAT($U$3,"_",B21,"_",$U$2,"_",Parámetros!$C$6),DATA_KPI!$A:$H,6,FALSE),0) -> 0 | V21: =IFERROR(VLOOKUP(_xlfn.CONCAT($V$3,"_",B21,"_",$U$2,"_",Parámetros!$C$6),DATA_KPI!$A:$H,6,FALSE),0) -> 0 | W21: =IFERROR(+V21/U21,0) -> 0 | X21: =IFERROR(VLOOKUP(_xlfn.CONCAT($V$3,"_",B21,"_",$U$2,"_",Parámetros!$C$6),DATA_KPI_PRE!A:F,6,FALSE),0) -> 0 | Y21: =IFERROR(+(V21/X21)-1,0) -> 0 | AA21: =IFERROR(VLOOKUP(_xlfn.CONCAT($AA$3,"_",B21,"_",$AA$2,"_",Parámetros!$C$6),DATA_KPI!$A:$H,6,FALSE),0) -> 12371.68 | AB21: =IFERROR(VLOOKUP(_xlfn.CONCAT($AB$3,"_",B21,"_",$AA$2,"_",Parámetros!$C$6),DATA_KPI!$A:$H,6,FALSE),0) -> 0 | AC21: =IFERROR(+AB21/AA21,0) -> 0 | AD21: =IFERROR(VLOOKUP(_xlfn.CONCAT($AB$3,"_",B21,"_",$AA$2,"_",Parámetros!$C$6),DATA_KPI_PRE!A:F,6,FALSE),0) -> 0 | AE21: =IFERROR(+(AB21/AD21)-1,0) -> 0 | AG21: =IFERROR(VLOOKUP(_xlfn.CONCAT($AG$3,"_",B21,"_",$AG$2,"_",Parámetros!$C$6),DATA_KPI!$A:$H,6,FALSE),0) -> 2146447.4 | AH21: =IFERROR(VLOOKUP(_xlfn.CONCAT($AH$3,"_",B21,"_",$AG$2,"_",Parámetros!$C$6),DATA_KPI!$A:$H,6,FALSE),0) -> 2761031.7 | AI21: =IFERROR(+AH21/AG21,0) -> 1.2863263 | AJ21: =IFERROR(VLOOKUP(_xlfn.CONCAT($AH$3,"_",B21,"_",$AG$2,"_",Parámetros!$C$6),DATA_KPI_PRE!A:F,6,FALSE),0) -> 2357683.2 | AK21: =IFERROR(+(AH21/AJ21)-1,0) -> 0.17107831 | AM21: =IFERROR(VLOOKUP(_xlfn.CONCAT($AM$3,"_",B21,"_",$AM$2,"_",Parámetros!$C$6),DATA_KPI!$A:$H,6,FALSE),0) -> 0 | AN21: =IFERROR(VLOOKUP(_xlfn.CONCAT($AN$3,"_",B21,"_",$AM$2,"_",Parámetros!$C$6),DATA_KPI!$A:$H,6,FALSE),0) -> 0 | AO21: =IFERROR(+AN21/AM21,0) -> 0 | AP21: =IFERROR(VLOOKUP(_xlfn.CONCAT($AN$3,"_",B21,"_",$AM$2,"_",Parámetros!$C$6),DATA_KPI_PRE!A:F,6,FALSE),0) -> 0 | AQ21: =IFERROR(+(AN21/AP21)-1,0) -> 0 | AS21: =IFERROR(J21/D21,0) -> 0.6832945 | AT21: =IFERROR(P21/D21,0) -> 0.034290641 | AU21: =IFERROR(V21/D21,0) -> 0 | AV21: =IFERROR(AB21/D21,0) -> 0 | AW21: =IFERROR(AH21/D21,0) -> 0.28241486 | AX21: =IFERROR(AN21/D21,0) -> 0 | AY21: =SUM(AS21:AX21) -> 1
